Workbook

Sheet لوحة القيادة
A1: لوحة قيادة الأداء — دعم قرار أصحاب المصلحة
A2: نظرة شاملة على أداء المنشأة عبر الأقسام · مبنية على المخرجات والأثر
B4: عدد الموظفين | D4: متوسط الأداء العام | F4: يفوق التوقعات (75+) | H4: تحت المستوى (<60) | J4: أعلى موظف أداءً
B5: =COUNT('قاعدة البيانات'!$D$3:$D$152) -> 105 | D5: =ROUND(AVERAGE('قاعدة البيانات'!$D$3:$D$152),1) -> 78.4 | F5: =COUNTIF('قاعدة البيانات'!$D$3:$D$152,">=75") -> 67 | H5: =COUNTIF('قاعدة البيانات'!$D$3:$D$152,"<60") -> 13 | J5: =INDEX('قاعدة البيانات'!$B$3:$B$152,MATCH(MAX('قاعدة البيانات'!$G$3:$G$152),'قاعدة البيانات'!$G$3:$G$152,0)) -> مها الخالدي
B8: مقارنة الأقسام | H8: أعلى 5 أداءً
B9: القسم | C9: المتوسط | D9: العدد | E9: النتيجة | H9: الموظف | I9: القسم | J9: الدرجة
B10: التسويق والمبيعات | C10: ='التسويق والمبيعات'!O30 -> 80.4 | D10: =COUNTA('التسويق والمبيعات'!B4:B28) -> 18 | E10: =IF(C10="","",IF(C10>=90,"أداء متميز",IF(C10>=75,"يفوق التوقعات",IF(C10>=60,"يلبّي التوقعات",IF(C10>=45,"يحتاج تطوير","غير مُرضٍ"))))) -> يفوق التوقعات | H10: =IFERROR(INDEX('قاعدة البيانات'!$B$3:$B$152,MATCH(LARGE('قاعدة البيانات'!$G$3:$G$152,1),'قاعدة البيانات'!$G$3:$G$152,0)),"") -> مها الخالدي | I10: =IFERROR(INDEX('قاعدة البيانات'!$C$3:$C$152,MATCH(LARGE('قاعدة البيانات'!$G$3:$G$152,1),'قاعدة البيانات'!$G$3:$G$152,0)),"") -> التسويق والمبيعات | J10: =IFERROR(ROUND(LARGE('قاعدة البيانات'!$D$3:$D$152,1),1),"") -> 100
B11: استقطاب المواهب | C11: ='استقطاب المواهب'!O30 -> 75.2 | D11: =COUNTA('استقطاب المواهب'!B4:B28) -> 18 | E11: =IF(C11="","",IF(C11>=90,"أداء متميز",IF(C11>=75,"يفوق التوقعات",IF(C11>=60,"يلبّي التوقعات",IF(C11>=45,"يحتاج تطوير","غير مُرضٍ"))))) -> يفوق التوقعات | H11: =IFERROR(INDEX('قاعدة البيانات'!$B$3:$B$152,MATCH(LARGE('قاعدة البيانات'!$G$3:$G$152,2),'قاعدة البيانات'!$G$3:$G$152,0)),"") -> سعود الشهراني | I11: =IFERROR(INDEX('قاعدة البيانات'!$C$3:$C$152,MATCH(LARGE('قاعدة البيانات'!$G$3:$G$152,2),'قاعدة البيانات'!$G$3:$G$152,0)),"") -> استقطاب المواهب | J11: =IFERROR(ROUND(LARGE('قاعدة البيانات'!$D$3:$D$152,2),1),"") -> 99.8
B12: التعلم والتطوير | C12: ='التعلم والتطوير'!O30 -> 75.8 | D12: =COUNTA('التعلم والتطوير'!B4:B28) -> 18 | E12: =IF(C12="","",IF(C12>=90,"أداء متميز",IF(C12>=75,"يفوق التوقعات",IF(C12>=60,"يلبّي التوقعات",IF(C12>=45,"يحتاج تطوير","غير مُرضٍ"))))) -> يفوق التوقعات | H12: =IFERROR(INDEX('قاعدة البيانات'!$B$3:$B$152,MATCH(LARGE('قاعدة البيانات'!$G$3:$G$152,3),'قاعدة البيانات'!$G$3:$G$152,0)),"") -> عبدالله العنزي | I12: =IFERROR(INDEX('قاعدة البيانات'!$C$3:$C$152,MATCH(LARGE('قاعدة البيانات'!$G$3:$G$152,3),'قاعدة البيانات'!$G$3:$G$152,0)),"") -> استقطاب المواهب | J12: =IFERROR(ROUND(LARGE('قاعدة البيانات'!$D$3:$D$152,3),1),"") -> 99.5
B13: نجاح العملاء | C13: ='نجاح العملاء'!O30 -> 77.6 | D13: =COUNTA('نجاح العملاء'!B4:B28) -> 18 | E13: =IF(C13="","",IF(C13>=90,"أداء متميز",IF(C13>=75,"يفوق التوقعات",IF(C13>=60,"يلبّي التوقعات",IF(C13>=45,"يحتاج تطوير","غير مُرضٍ"))))) -> يفوق التوقعات | H13: =IFERROR(INDEX('قاعدة البيانات'!$B$3:$B$152,MATCH(LARGE('قاعدة البيانات'!$G$3:$G$152,4),'قاعدة البيانات'!$G$3:$G$152,0)),"") -> طارق الشمري | I13: =IFERROR(INDEX('قاعدة البيانات'!$C$3:$C$152,MATCH(LARGE('قاعدة البيانات'!$G$3:$G$152,4),'قاعدة البيانات'!$G$3:$G$152,0)),"") -> تطوير البرمجيات | J13: =IFERROR(ROUND(LARGE('قاعدة البيانات'!$D$3:$D$152,4),1),"") -> 99.4
B14: تطوير البرمجيات | C14: ='تطوير البرمجيات'!O30 -> 84.3 | D14: =COUNTA('تطوير البرمجيات'!B4:B28) -> 17 | E14: =IF(C14="","",IF(C14>=90,"أداء متميز",IF(C14>=75,"يفوق التوقعات",IF(C14>=60,"يلبّي التوقعات",IF(C14>=45,"يحتاج تطوير","غير مُرضٍ"))))) -> يفوق التوقعات | H14: =IFERROR(INDEX('قاعدة البيانات'!$B$3:$B$152,MATCH(LARGE('قاعدة البيانات'!$G$3:$G$152,5),'قاعدة البيانات'!$G$3:$G$152,0)),"") -> سعود الزهراني | I14: =IFERROR(INDEX('قاعدة البيانات'!$C$3:$C$152,MATCH(LARGE('قاعدة البيانات'!$G$3:$G$152,5),'قاعدة البيانات'!$G$3:$G$152,0)),"") -> تطوير البرمجيات | J14: =IFERROR(ROUND(LARGE('قاعدة البيانات'!$D$3:$D$152,5),1),"") -> 99.3
B15: المالية والمحاسبة | C15: ='المالية والمحاسبة'!O30 -> 77.6 | D15: =COUNTA('المالية والمحاسبة'!B4:B28) -> 16 | E15: =IF(C15="","",IF(C15>=90,"أداء متميز",IF(C15>=75,"يفوق التوقعات",IF(C15>=60,"يلبّي التوقعات",IF(C15>=45,"يحتاج تطوير","غير مُرضٍ"))))) -> يفوق التوقعات
B16: الإجمالي | C16: =ROUND(AVERAGE('قاعدة البيانات'!$D$3:$D$152),1) -> 78.4 | D16: =COUNT('قاعدة البيانات'!$D$3:$D$152) -> 105 | E16: =IF(C16="","",IF(C16>=90,"أداء متميز",IF(C16>=75,"يفوق التوقعات",IF(C16>=60,"يلبّي التوقعات",IF(C16>=45,"يحتاج تطوير","غير مُرضٍ"))))) -> يفوق التوقعات
H17: قائمة المخاطر — أدنى 5 (تحتاج تدخّل)
H18: الموظف | I18: القسم | J18: الدرجة
H19: =IFERROR(INDEX('قاعدة البيانات'!$B$3:$B$152,MATCH(SMALL('قاعدة البيانات'!$G$3:$G$152,1),'قاعدة البيانات'!$G$3:$G$152,0)),"") -> ناصر الحربي | I19: =IFERROR(INDEX('قاعدة البيانات'!$C$3:$C$152,MATCH(SMALL('قاعدة البيانات'!$G$3:$G$152,1),'قاعدة البيانات'!$G$3:$G$152,0)),"") -> استقطاب المواهب | J19: =IFERROR(ROUND(SMALL('قاعدة البيانات'!$D$3:$D$152,1),1),"") -> 40.5
H20: =IFERROR(INDEX('قاعدة البيانات'!$B$3:$B$152,MATCH(SMALL('قاعدة البيانات'!$G$3:$G$152,2),'قاعدة البيانات'!$G$3:$G$152,0)),"") -> بندر الرشيدي | I20: =IFERROR(INDEX('قاعدة البيانات'!$C$3:$C$152,MATCH(SMALL('قاعدة البيانات'!$G$3:$G$152,2),'قاعدة البيانات'!$G$3:$G$152,0)),"") -> استقطاب المواهب | J20: =IFERROR(ROUND(SMALL('قاعدة البيانات'!$D$3:$D$152,2),1),"") -> 43.1
H21: =IFERROR(INDEX('قاعدة البيانات'!$B$3:$B$152,MATCH(SMALL('قاعدة البيانات'!$G$3:$G$152,3),'قاعدة البيانات'!$G$3:$G$152,0)),"") -> غادة الحربي | I21: =IFERROR(INDEX('قاعدة البيانات'!$C$3:$C$152,MATCH(SMALL('قاعدة البيانات'!$G$3:$G$152,3),'قاعدة البيانات'!$G$3:$G$152,0)),"") -> التعلم والتطوير | J21: =IFERROR(ROUND(SMALL('قاعدة البيانات'!$D$3:$D$152,3),1),"") -> 46.2
H22: =IFERROR(INDEX('قاعدة البيانات'!$B$3:$B$152,MATCH(SMALL('قاعدة البيانات'!$G$3:$G$152,4),'قاعدة البيانات'!$G$3:$G$152,0)),"") -> شهد القحطاني | I22: =IFERROR(INDEX('قاعدة البيانات'!$C$3:$C$152,MATCH(SMALL('قاعدة البيانات'!$G$3:$G$152,4),'قاعدة البيانات'!$G$3:$G$152,0)),"") -> المالية والمحاسبة | J22: =IFERROR(ROUND(SMALL('قاعدة البيانات'!$D$3:$D$152,4),1),"") -> 48.1
H23: =IFERROR(INDEX('قاعدة البيانات'!$B$3:$B$152,MATCH(SMALL('قاعدة البيانات'!$G$3:$G$152,5),'قاعدة البيانات'!$G$3:$G$152,0)),"") -> مشعل العتيبي | I23: =IFERROR(INDEX('قاعدة البيانات'!$C$3:$C$152,MATCH(SMALL('قاعدة البيانات'!$G$3:$G$152,5),'قاعدة البيانات'!$G$3:$G$152,0)),"") -> نجاح العملاء | J23: =IFERROR(ROUND(SMALL('قاعدة البيانات'!$D$3:$D$152,5),1),"") -> 48.7

Sheet المنهجية
A1: منهجية مؤشرات الأداء — تحليل سلسلة القيمة (Value Flow-Analysis)
A2: إعداد: Abdulrahim Obaid — CPC · HRIS | المؤشر يُبنى من القيمة لا من الرقم
A4: المستويات الخمسة لبناء أي مؤشر
A5: م | B5: المستوى | C5: السؤال الذي يجيب عليه | D5: ماذا نقيس
A6: 1 | B6: الأهداف | C6: ما الغاية الاستراتيجية المراد تحقيقها؟ | D6: اتجاه عام
A7: 2 | B7: المدخلات | C7: ما الموارد البشرية والمالية والتقنية؟ | D7: موارد (سياق)
A8: 3 | B8: العمليات | C8: ما الذي يحدث فعلياً داخل التنفيذ؟ | D8: الوقت والكفاءة
A9: 4 | B9: المخرجات | C9: ما الذي أُنجِز بشكل مباشر؟ | D9: نتائج قابلة للعدّ
A10: 5 | B10: النتائج والأثر | C10: هل انعكس على العميل أو الأعمال؟ | D10: القيمة المضافة
A12: القواعد الذهبية
A13: — ابدأ من الهدف والقيمة، لا من الرقم.
A14: — صفر نقطة على الحضور — الأداء يُقاس بالمخرجات والأثر.
A15: — كل مؤشر يأخذ وزناً نسبياً، ومجموع الأوزان = 100.
A16: — اربط كل مؤشر بموقعه في سلسلة القيمة قبل تحديد وزنه.
A17: — ركّز الأوزان على المخرجات والأثر.
A18: — المؤشر القوي يكشف أين الخلل، لا يراقب النشاط فقط.
A19: — الدرجة تُحتسب آلياً — تقييم بلا عواطف.
A21: سلّم التقييم (من 100)
A22: 90 – 100 | C22: أداء متميز
A23: 75 – 89 | C23: يفوق التوقعات
A24: 60 – 74 | C24: يلبّي التوقعات
A25: 45 – 59 | C25: يحتاج تطوير
A26: أقل من 45 | C26: غير مُرضٍ

Sheet دليل المؤشرات
A1: دليل المؤشرات المعتمد — مرجع الإعدادات (المصدر الوحيد للأوزان والأهداف)
A2: عدّل الوزن أو الهدف هنا فتتحدّث درجات كل الأقسام آلياً · مجموع أوزان كل قسم = 100
A3: القسم | B3: المؤشر (KPI) | C3: مرحلة القيمة | D3: الاتجاه | E3: الوزن | F3: الهدف
A4: التسويق والمبيعات | B4: المبيعات المنسوبة للمحتوى (ر.س) | C4: الأثر | D4: ↑ | E4: 30 | F4: 60000
B5: عدد المقاطع المنشورة | C5: العمليات | D5: ↑ | E5: 20 | F5: 90
B6: مبيعات لكل 1000 مشاهدة | C6: الكفاءة | D6: ↑ | E6: 15 | F6: 50
B7: معدل الطلبات لكل مقطع | C7: الكفاءة | D7: ↑ | E7: 15 | F7: 9
B8: المتابعون الجدد | C8: المخرجات | D8: ↑ | E8: 10 | F8: 5000
B9: متوسط قيمة الطلب (ر.س) | C9: الأثر | D9: ↑ | E9: 10 | F9: 155
A10: مجموع الأوزان | E10: =SUM(E4:E9) -> 100
A11: استقطاب المواهب | B11: جودة التوظيف % اجتياز التجربة | C11: الأثر | D11: ↑ | E11: 25 | F11: 90
B12: زمن شغل الوظيفة (يوم) | C12: العمليات | D12: ↓ | E12: 20 | F12: 30
B13: عدد التعيينات المكتملة | C13: المخرجات | D13: ↑ | E13: 15 | F13: 8
B14: نسبة قبول العروض % | C14: العمليات | D14: ↑ | E14: 15 | F14: 80
B15: تكلفة التوظيف (ر.س) | C15: المدخلات | D15: ↓ | E15: 15 | F15: 4000
B16: رضا المدير الطالب (1-10) | C16: الأثر | D16: ★ | E16: 10 | F16: 10
A17: مجموع الأوزان | E17: =SUM(E11:E16) -> 100
A18: التعلم والتطوير | B18: تحسّن الأداء بعد التدريب % | C18: الأثر | D18: ↑ | E18: 25 | F18: 15
B19: نسبة إكمال البرامج % | C19: المخرجات | D19: ↑ | E19: 20 | F19: 85
B20: تغطية خطط التطوير IDP % | C20: العمليات | D20: ↑ | E20: 15 | F20: 90
B21: رضا المتدربين (من 5) | C21: الأثر | D21: ↑ | E21: 15 | F21: 4.5
B22: ساعات التدريب المنفّذة | C22: العمليات | D22: ↑ | E22: 15 | F22: 120
B23: احتفاظ بالمواهب المدرّبة % | C23: الأثر | D23: ↑ | E23: 10 | F23: 90
A24: مجموع الأوزان | E24: =SUM(E18:E23) -> 100
A25: نجاح العملاء | B25: نسبة التجديد Retention % | C25: الأثر | D25: ↑ | E25: 25 | F25: 85
B26: الحل من أول تواصل FCR % | C26: المخرجات | D26: ↑ | E26: 20 | F26: 80
B27: رضا العملاء CSAT % | C27: الأثر | D27: ↑ | E27: 20 | F27: 90
B28: زمن الاستجابة الأولى (ساعة) | C28: العمليات | D28: ↓ | E28: 15 | F28: 2
B29: صافي الترويج NPS | C29: الأثر | D29: ↑ | E29: 10 | F29: 50
B30: عدد التذاكر المغلقة | C30: المخرجات | D30: ↑ | E30: 10 | F30: 200
A31: مجموع الأوزان | E31: =SUM(E25:E30) -> 100
A32: تطوير البرمجيات | B32: التسليم في الموعد % | C32: المخرجات | D32: ↑ | E32: 20 | F32: 90
B33: استقرار النظام Uptime % | C33: الأثر | D33: ↑ | E33: 20 | F33: 99.5
B34: الأخطاء بعد الإطلاق | C34: الجودة | D34: ↓ | E34: 15 | F34: 5
B35: نقاط القصة المنجزة | C35: المخرجات | D35: ↑ | E35: 15 | F35: 40
B36: تغطية الاختبارات % | C36: العمليات | D36: ↑ | E36: 15 | F36: 80
B37: جودة الكود ومراجعة PR (1-10) | C37: العمليات | D37: ★ | E37: 15 | F37: 10
A38: مجموع الأوزان | E38: =SUM(E32:E37) -> 100
A39: المالية والمحاسبة | B39: الفواتير المحصّلة في الموعد % | C39: الأثر | D39: ↑ | E39: 25 | F39: 90
B40: دقة التقارير المالية % | C40: الجودة | D40: ↑ | E40: 20 | F40: 98
...

Sheet التسويق والمبيعات
A1: بطاقة مؤشرات الأداء — التسويق بالمحتوى والمبيعات | المجموع 100 نقطة · صفر على الحضور
A2: # | B2: اسم الموظف | C2: المبيعات المنسوبة للمحتوى (ر.س) | D2: عدد المقاطع المنشورة | E2: مبيعات لكل 1000 مشاهدة | F2: معدل الطلبات لكل مقطع | G2: المتابعون الجدد | H2: متوسط قيمة الطلب (ر.س) | I2: د1 | J2: د2 | K2: د3 | L2: د4 | M2: د5 | N2: د6 | O2: الإجمالي | P2: النتيجة
B3: الهدف ← | → الوزن | C3: ='دليل المؤشرات'!F4 -> 60000 | D3: ='دليل المؤشرات'!F5 -> 90 | E3: ='دليل المؤشرات'!F6 -> 50 | F3: ='دليل المؤشرات'!F7 -> 9 | G3: ='دليل المؤشرات'!F8 -> 5000 | H3: ='دليل المؤشرات'!F9 -> 155 | I3: ='دليل المؤشرات'!E4 -> 30 | J3: ='دليل المؤشرات'!E5 -> 20 | K3: ='دليل المؤشرات'!E6 -> 15 | L3: ='دليل المؤشرات'!E7 -> 15 | M3: ='دليل المؤشرات'!E8 -> 10 | N3: ='دليل المؤشرات'!E9 -> 10 | O3: 100
A4: 1 | B4: فهد القحطاني | C4: 61754 | D4: 80 | E4: 49 | F4: 9.4 | G4: 4560 | H4: 137 | I4: =IF($B4="","",IF(C4="","",IFERROR(ROUND(IF('دليل المؤشرات'!$D$4="↓",MIN('دليل المؤشرات'!$F$4/C4,1),IF('دليل المؤشرات'!$D$4="★",C4/10,MIN(C4/'دليل المؤشرات'!$F$4,1)))*'دليل المؤشرات'!$E$4,1),0))) -> 30 | J4: =IF($B4="","",IF(D4="","",IFERROR(ROUND(IF('دليل المؤشرات'!$D$5="↓",MIN('دليل المؤشرات'!$F$5/D4,1),IF('دليل المؤشرات'!$D$5="★",D4/10,MIN(D4/'دليل المؤشرات'!$F$5,1)))*'دليل المؤشرات'!$E$5,1),0))) -> 17.8 | K4: =IF($B4="","",IF(E4="","",IFERROR(ROUND(IF('دليل المؤشرات'!$D$6="↓",MIN('دليل المؤشرات'!$F$6/E4,1),IF('دليل المؤشرات'!$D$6="★",E4/10,MIN(E4/'دليل المؤشرات'!$F$6,1)))*'دليل المؤشرات'!$E$6,1),0))) -> 14.7 | L4: =IF($B4="","",IF(F4="","",IFERROR(ROUND(IF('دليل المؤشرات'!$D$7="↓",MIN('دليل المؤشرات'!$F$7/F4,1),IF('دليل المؤشرات'!$D$7="★",F4/10,MIN(F4/'دليل المؤشرات'!$F$7,1)))*'دليل المؤشرات'!$E$7,1),0))) -> 15 | M4: =IF($B4="","",IF(G4="","",IFERROR(ROUND(IF('دليل المؤشرات'!$D$8="↓",MIN('دليل المؤشرات'!$F$8/G4,1),IF('دليل المؤشرات'!$D$8="★",G4/10,MIN(G4/'دليل المؤشرات'!$F$8,1)))*'دليل المؤشرات'!$E$8,1),0))) -> 9.1 | N4: =IF($B4="","",IF(H4="","",IFERROR(ROUND(IF('دليل المؤشرات'!$D$9="↓",MIN('دليل المؤشرات'!$F$9/H4,1),IF('دليل المؤشرات'!$D$9="★",H4/10,MIN(H4/'دليل المؤشرات'!$F$9,1)))*'دليل المؤشرات'!$E$9,1),0))) -> 8.8 | O4: =IF(B4="","",ROUND(SUM(I4:N4),1)) -> 95.4 | P4: =IF(O4="","",IF(O4>=90,"أداء متميز",IF(O4>=75,"يفوق التوقعات",IF(O4>=60,"يلبّي التوقعات",IF(O4>=45,"يحتاج تطوير","غير مُرضٍ"))))) -> أداء متميز
A5: 2 | B5: هند القحطاني | C5: 43805 | D5: 70 | E5: 35 | F5: 7 | G5: 4195 | H5: 122 | I5: =IF($B5="","",IF(C5="","",IFERROR(ROUND(IF('دليل المؤشرات'!$D$4="↓",MIN('دليل المؤشرات'!$F$4/C5,1),IF('دليل المؤشرات'!$D$4="★",C5/10,MIN(C5/'دليل المؤشرات'!$F$4,1)))*'دليل المؤشرات'!$E$4,1),0))) -> 21.9 | J5: =IF($B5="","",IF(D5="","",IFERROR(ROUND(IF('دليل المؤشرات'!$D$5="↓",MIN('دليل المؤشرات'!$F$5/D5,1),IF('دليل المؤشرات'!$D$5="★",D5/10,MIN(D5/'دليل المؤشرات'!$F$5,1)))*'دليل المؤشرات'!$E$5,1),0))) -> 15.6 | K5: =IF($B5="","",IF(E5="","",IFERROR(ROUND(IF('دليل المؤشرات'!$D$6="↓",MIN('دليل المؤشرات'!$F$6/E5,1),IF('دليل المؤشرات'!$D$6="★",E5/10,MIN(E5/'دليل المؤشرات'!$F$6,1)))*'دليل المؤشرات'!$E$6,1),0))) -> 10.5 | L5: =IF($B5="","",IF(F5="","",IFERROR(ROUND(IF('دليل المؤشرات'!$D$7="↓",MIN('دليل المؤشرات'!$F$7/F5,1),IF('دليل المؤشرات'!$D$7="★",F5/10,MIN(F5/'دليل المؤشرات'!$F$7,1)))*'دليل المؤشرات'!$E$7,1),0))) -> 11.7 | M5: =IF($B5="","",IF(G5="","",IFERROR(ROUND(IF('دليل المؤشرات'!$D$8="↓",MIN('دليل المؤشرات'!$F$8/G5,1),IF('دليل المؤشرات'!$D$8="★",G5/10,MIN(G5/'دليل المؤشرات'!$F$8,1)))*'دليل المؤشرات'!$E$8,1),0))) -> 8.4 | N5: =IF($B5="","",IF(H5="","",IFERROR(ROUND(IF('دليل المؤشرات'!$D$9="↓",MIN('دليل المؤشرات'!$F$9/H5,1),IF('دليل المؤشرات'!$D$9="★",H5/10,MIN(H5/'دليل المؤشرات'!$F$9,1)))*'دليل المؤشرات'!$E$9,1),0))) -> 7.9 | O5: =IF(B5="","",ROUND(SUM(I5:N5),1)) -> 76 | P5: =IF(O5="","",IF(O5>=90,"أداء متميز",IF(O5>=75,"يفوق التوقعات",IF(O5>=60,"يلبّي التوقعات",IF(O5>=45,"يحتاج تطوير","غير مُرضٍ"))))) -> يفوق التوقعات
A6: 3 | B6: رغد المطيري | C6: 42146 | D6: 66 | E6: 39 | F6: 6.4 | G6: 3797 | H6: 121 | I6: =IF($B6="","",IF(C6="","",IFERROR(ROUND(IF('دليل المؤشرات'!$D$4="↓",MIN('دليل المؤشرات'!$F$4/C6,1),IF('دليل المؤشرات'!$D$4="★",C6/10,MIN(C6/'دليل المؤشرات'!$F$4,1)))*'دليل المؤشرات'!$E$4,1),0))) -> 21.1 | J6: =IF($B6="","",IF(D6="","",IFERROR(ROUND(IF('دليل المؤشرات'!$D$5="↓",MIN('دليل المؤشرات'!$F$5/D6,1),IF('دليل المؤشرات'!$D$5="★",D6/10,MIN(D6/'دليل المؤشرات'!$F$5,1)))*'دليل المؤشرات'!$E$5,1),0))) -> 14.7 | K6: =IF($B6="","",IF(E6="","",IFERROR(ROUND(IF('دليل المؤشرات'!$D$6="↓",MIN('دليل المؤشرات'!$F$6/E6,1),IF('دليل المؤشرات'!$D$6="★",E6/10,MIN(E6/'دليل المؤشرات'!$F$6,1)))*'دليل المؤشرات'!$E$6,1),0))) -> 11.7 | L6: =IF($B6="","",IF(F6="","",IFERROR(ROUND(IF('دليل المؤشرات'!$D$7="↓",MIN('دليل المؤشرات'!$F$7/F6,1),IF('دليل المؤشرات'!$D$7="★",F6/10,MIN(F6/'دليل المؤشرات'!$F$7,1)))*'دليل المؤشرات'!$E$7,1),0))) -> 10.7 | M6: =IF($B6="","",IF(G6="","",IFERROR(ROUND(IF('دليل المؤشرات'!$D$8="↓",MIN('دليل المؤشرات'!$F$8/G6,1),IF('دليل المؤشرات'!$D$8="★",G6/10,MIN(G6/'دليل المؤشرات'!$F$8,1)))*'دليل المؤشرات'!$E$8,1),0))) -> 7.6 | N6: =IF($B6="","",IF(H6="","",IFERROR(ROUND(IF('دليل المؤشرات'!$D$9="↓",MIN('دليل المؤشرات'!$F$9/H6,1),IF('دليل المؤشرات'!$D$9="★",H6/10,MIN(H6/'دليل المؤشرات'!$F$9,1)))*'دليل المؤشرات'!$E$9,1),0))) -> 7.8 | O6: =IF(B6="","",ROUND(SUM(I6:N6),1)) -> 73.6 | P6: =IF(O6="","",IF(O6>=90,"أداء متميز",IF(O6>=75,"يفوق التوقعات",IF(O6>=60,"يلبّي التوقعات",IF(O6>=45,"يحتاج تطوير","غير مُرضٍ"))))) -> يلبّي التوقعات
A7: 4 | B7: وعد البقمي | C7: 48117 | D7: 74 | E7: 36 | F7: 7.2 | G7: 3715 | H7: 113 | I7: =IF($B7="","",IF(C7="","",IFERROR(ROUND(IF('دليل المؤشرات'!$D$4="↓",MIN('دليل المؤشرات'!$F$4/C7,1),IF('دليل المؤشرات'!$D$4="★",C7/10,MIN(C7/'دليل المؤشرات'!$F$4,1)))*'دليل المؤشرات'!$E$4,1),0))) -> 24.1 | J7: =IF($B7="","",IF(D7="","",IFERROR(ROUND(IF('دليل المؤشرات'!$D$5="↓",MIN('دليل المؤشرات'!$F$5/D7,1),IF('دليل المؤشرات'!$D$5="★",D7/10,MIN(D7/'دليل المؤشرات'!$F$5,1)))*'دليل المؤشرات'!$E$5,1),0))) -> 16.4 | K7: =IF($B7="","",IF(E7="","",IFERROR(ROUND(IF('دليل المؤشرات'!$D$6="↓",MIN('دليل المؤشرات'!$F$6/E7,1),IF('دليل المؤشرات'!$D$6="★",E7/10,MIN(E7/'دليل المؤشرات'!$F$6,1)))*'دليل المؤشرات'!$E$6,1),0))) -> 10.8 | L7: =IF($B7="","",IF(F7="","",IFERROR(ROUND(IF('دليل المؤشرات'!$D$7="↓",MIN('دليل المؤشرات'!$F$7/F7,1),IF('دليل المؤشرات'!$D$7="★",F7/10,MIN(F7/'دليل المؤشرات'!$F$7,1)))*'دليل المؤشرات'!$E$7,1),0))) -> 12 | M7: =IF($B7="","",IF(G7="","",IFERROR(ROUND(IF('دليل المؤشرات'!$D$8="↓",MIN('دليل المؤشرات'!$F$8/G7,1),IF('دليل المؤشرات'!$D$8="★",G7/10,MIN(G7/'دليل المؤشرات'!$F$8,1)))*'دليل المؤشرات'!$E$8,1),0))) -> 7.4 | N7: =IF($B7="","",IF(H7="","",IFERROR(ROUND(IF('دليل المؤشرات'!$D$9="↓",MIN('دليل المؤشرات'!$F$9/H7,1),IF('دليل المؤشرات'!$D$9="★",H7/10,MIN(H7/'دليل المؤشرات'!$F$9,1)))*'دليل المؤشرات'!$E$9,1),0))) -> 7.3 | O7: =IF(B7="","",ROUND(SUM(I7:N7),1)) -> 78 | P7: =IF(O7="","",IF(O7>=90,"أداء متميز",IF(O7>=75,"يفوق التوقعات",IF(O7>=60,"يلبّي التوقعات",IF(O7>=45,"يحتاج تطوير","غير مُرضٍ"))))) -> يفوق التوقعات
A8: 5 | B8: بيان الغامدي | C8: 46339 | D8: 70 | E8: 41 | F8: 6.9 | G8: 4192 | H8: 116 | I8: =IF($B8="","",IF(C8="","",IFERROR(ROUND(IF('دليل المؤشرات'!$D$4="↓",MIN('دليل المؤشرات'!$F$4/C8,1),IF('دليل المؤشرات'!$D$4="★",C8/10,MIN(C8/'دليل المؤشرات'!$F$4,1)))*'دليل المؤشرات'!$E$4,1),0))) -> 23.2 | J8: =IF($B8="","",IF(D8="","",IFERROR(ROUND(IF('دليل المؤشرات'!$D$5="↓",MIN('دليل المؤشرات'!$F$5/D8,1),IF('دليل المؤشرات'!$D$5="★",D8/10,MIN(D8/'دليل المؤشرات'!$F$5,1)))*'دليل المؤشرات'!$E$5,1),0))) -> 15.6 | K8: =IF($B8="","",IF(E8="","",IFERROR(ROUND(IF('دليل المؤشرات'!$D$6="↓",MIN('دليل المؤشرات'!$F$6/E8,1),IF('دليل المؤشرات'!$D$6="★",E8/10,MIN(E8/'دليل المؤشرات'!$F$6,1)))*'دليل المؤشرات'!$E$6,1),0))) -> 12.3 | L8: =IF($B8="","",IF(F8="","",IFERROR(ROUND(IF('دليل المؤشرات'!$D$7="↓",MIN('دليل المؤشرات'!$F$7/F8,1),IF('دليل المؤشرات'!$D$7="★",F8/10,MIN(F8/'دليل المؤشرات'!$F$7,1)))*'دليل المؤشرات'!$E$7,1),0))) -> 11.5 | M8: =IF($B8="","",IF(G8="","",IFERROR(ROUND(IF('دليل المؤشرات'!$D$8="↓",MIN('دليل المؤشرات'!$F$8/G8,1),IF('دليل المؤشرات'!$D$8="★",G8/10,MIN(G8/'دليل المؤشرات'!$F$8,1)))*'دليل المؤشرات'!$E$8,1),0))) -> 8.4 | N8: =IF($B8="","",IF(H8="","",IFERROR(ROUND(IF('دليل المؤشرات'!$D$9="↓",MIN('دليل المؤشرات'!$F$9/H8,1),IF('دليل المؤشرات'!$D$9="★",H8/10,MIN(H8/'دليل المؤشرات'!$F$9,1)))*'دليل المؤشرات'!$E$9,1),0))) -> 7.5 | O8: =IF(B8="","",ROUND(SUM(I8:N8),1)) -> 78.5 | P8: =IF(O8="","",IF(O8>=90,"أداء متميز",IF(O8>=75,"يفوق التوقعات",IF(O8>=60,"يلبّي التوقعات",IF(O8>=45,"يحتاج تطوير","غير مُرضٍ"))))) -> يفوق التوقعات
A9: 6 | B9: عبدالرحمن الحربي | C9: 39043 | D9: 53 | E9: 32 | F9: 5.7 | G9: 3364 | H9: 101 | I9: =IF($B9="","",IF(C9="","",IFERROR(ROUND(IF('دليل المؤشرات'!$D$4="↓",MIN('دليل المؤشرات'!$F$4/C9,1),IF('دليل المؤشرات'!$D$4="★",C9/10,MIN(C9/'دليل المؤشرات'!$F$4,1)))*'دليل المؤشرات'!$E$4,1),0))) -> 19.5 | J9: =IF($B9="","",IF(D9="","",IFERROR(ROUND(IF('دليل المؤشرات'!$D$5="↓",MIN('دليل المؤشرات'!$F$5/D9,1),IF('دليل المؤشرات'!$D$5="★",D9/10,MIN(D9/'دليل المؤشرات'!$F$5,1)))*'دليل المؤشرات'!$E$5,1),0))) -> 11.8 | K9: =IF($B9="","",IF(E9="","",IFERROR(ROUND(IF('دليل المؤشرات'!$D$6="↓",MIN('دليل المؤشرات'!$F$6/E9,1),IF('دليل المؤشرات'!$D$6="★",E9/10,MIN(E9/'دليل المؤشرات'!$F$6,1)))*'دليل المؤشرات'!$E$6,1),0))) -> 9.6 | L9: =IF($B9="","",IF(F9="","",IFERROR(ROUND(IF('دليل المؤشرات'!$D$7="↓",MIN('دليل المؤشرات'!$F$7/F9,1),IF('دليل المؤشرات'!$D$7="★",F9/10,MIN(F9/'دليل المؤشرات'!$F$7,1)))*'دليل المؤشرات'!$E$7,1),0))) -> 9.5 | M9: =IF($B9="","",IF(G9="","",IFERROR(ROUND(IF('دليل المؤشرات'!$D$8="↓",MIN('دليل المؤشرات'!$F$8/G9,1),IF('دليل المؤشرات'!$D$8="★",G9/10,MIN(G9/'دليل المؤشرات'!$F$8,1)))*'دليل المؤشرات'!$E$8,1),0))) -> 6.7 | N9: =IF($B9="","",IF(H9="","",IFERROR(ROUND(IF('دليل المؤشرات'!$D$9="↓",MIN('دليل المؤشرات'!$F$9/H9,1),IF('دليل المؤشرات'!$D$9="★",H9/10,MIN(H9/'دليل المؤشرات'!$F$9,1)))*'دليل المؤشرات'!$E$9,1),0))) -> 6.5 | O9: =IF(B9="","",ROUND(SUM(I9:N9),1)) -> 63.6 | P9: =IF(O9="","",IF(O9>=90,"أداء متميز",IF(O9>=75,"يفوق التوقعات",IF(O9>=60,"يلبّي التوقعات",IF(O9>=45,"يحتاج تطوير","غير مُرضٍ"))))) -> يلبّي التوقعات
A10: 7 | B10: ماجد الجهني | C10: 42346 | D10: 68 | E10: 33 | F10: 6.4 | G10: 3257 | H10: 115 | I10: =IF($B10="","",IF(C10="","",IFERROR(ROUND(IF('دليل المؤشرات'!$D$4="↓",MIN('دليل المؤشرات'!$F$4/C10,1),IF('دليل المؤشرات'!$D$4="★",C10/10,MIN(C10/'دليل المؤشرات'!$F$4,1)))*'دليل المؤشرات'!$E$4,1),0))) -> 21.2 | J10: =IF($B10="","",IF(D10="","",IFERROR(ROUND(IF('دليل المؤشرات'!$D$5="↓",MIN('دليل المؤشرات'!$F$5/D10,1),IF('دليل المؤشرات'!$D$5="★",D10/10,MIN(D10/'دليل المؤشرات'!$F$5,1)))*'دليل المؤشرات'!$E$5,1),0))) -> 15.1 | K10: =IF($B10="","",IF(E10="","",IFERROR(ROUND(IF('دليل المؤشرات'!$D$6="↓",MIN('دليل المؤشرات'!$F$6/E10,1),IF('دليل المؤشرات'!$D$6="★",E10/10,MIN(E10/'دليل المؤشرات'!$F$6,1)))*'دليل المؤشرات'!$E$6,1),0))) -> 9.9 | L10: =IF($B10="","",IF(F10="","",IFERROR(ROUND(IF('دليل المؤشرات'!$D$7="↓",MIN('دليل المؤشرات'!$F$7/F10,1),IF('دليل المؤشرات'!$D$7="★",F10/10,MIN(F10/'دليل المؤشرات'!$F$7,1)))*'دليل المؤشرات'!$E$7,1),0))) -> 10.7 | M10: =IF($B10="","",IF(G10="","",IFERROR(ROUND(IF('دليل المؤشرات'!$D$8="↓",MIN('دليل المؤشرات'!$F$8/G10,1),IF('دليل المؤشرات'!$D$8="★",G10/10,MIN(G10/'دليل المؤشرات'!$F$8,1)))*'دليل المؤشرات'!$E$8,1),0))) -> 6.5 | N10: =IF($B10="","",IF(H10="","",IFERROR(ROUND(IF('دليل المؤشرات'!$D$9="↓",MIN('دليل المؤشرات'!$F$9/H10,1),IF('دليل المؤشرات'!$D$9="★",H10/10,MIN(H10/'دليل المؤشرات'!$F$9,1)))*'دليل المؤشرات'!$E$9,1),0))) -> 7.4 | O10: =IF(B10="","",ROUND(SUM(I10:N10),1)) -> 70.8 | P10: =IF(O10="","",IF(O10>=90,"أداء متميز",IF(O10>=75,"يفوق التوقعات",IF(O10>=60,"يلبّي التوقعات",IF(O10>=45,"يحتاج تطوير","غير مُرضٍ"))))) -> يلبّي التوقعات
A11: 8 | B11: مها الخالدي | C11: 66325 | D11: 100 | E11: 51 | F11: 9.1 | G11: 5222 | H11: 172 | I11: =IF($B11="","",IF(C11="","",IFERROR(ROUND(IF('دليل المؤشرات'!$D$4="↓",MIN('دليل المؤشرات'!$F$4/C11,1),IF('دليل المؤشرات'!$D$4="★",C11/10,MIN(C11/'دليل المؤشرات'!$F$4,1)))*'دليل المؤشرات'!$E$4,1),0))) -> 30 | J11: =IF($B11="","",IF(D11="","",IFERROR(ROUND(IF('دليل المؤشرات'!$D$5="↓",MIN('دليل المؤشرات'!$F$5/D11,1),IF('دليل المؤشرات'!$D$5="★",D11/10,MIN(D11/'دليل المؤشرات'!$F$5,1)))*'دليل المؤشرات'!$E$5,1),0))) -> 20 | K11: =IF($B11="","",IF(E11="","",IFERROR(ROUND(IF('دليل المؤشرات'!$D$6="↓",MIN('دليل المؤشرات'!$F$6/E11,1),IF('دليل المؤشرات'!$D$6="★",E11/10,MIN(E11/'دليل المؤشرات'!$F$6,1)))*'دليل المؤشرات'!$E$6,1),0))) -> 15 | L11: =IF($B11="","",IF(F11="","",IFERROR(ROUND(IF('دليل المؤشرات'!$D$7="↓",MIN('دليل المؤشرات'!$F$7/F11,1),IF('دليل المؤشرات'!$D$7="★",F11/10,MIN(F11/'دليل المؤشرات'!$F$7,1)))*'دليل المؤشرات'!$E$7,1),0))) -> 15 | M11: =IF($B11="","",IF(G11="","",IFERROR(ROUND(IF('دليل المؤشرات'!$D$8="↓",MIN('دليل المؤشرات'!$F$8/G11,1),IF('دليل المؤشرات'!$D$8="★",G11/10,MIN(G11/'دليل المؤشرات'!$F$8,1)))*'دليل المؤشرات'!$E$8,1),0))) -> 10 | N11: =IF($B11="","",IF(H11="","",IFERROR(ROUND(IF('دليل المؤشرات'!$D$9="↓",MIN('دليل المؤشرات'!$F$9/H11,1),IF('دليل المؤشرات'!$D$9="★",H11/10,MIN(H11/'دليل المؤشرات'!$F$9,1)))*'دليل المؤشرات'!$E$9,1),0))) -> 10 | O11: =IF(B11="","",ROUND(SUM(I11:N11),1)) -> 100 | P11: =IF(O11="","",IF(O11>=90,"أداء متميز",IF(O11>=75,"يفوق التوقعات",IF(O11>=60,"يلبّي التوقعات",IF(O11>=45,"يحتاج تطوير","غير مُرضٍ"))))) -> أداء متميز
A12: 9 | B12: مشعل العنزي | C12: 55031 | D12: 73 | E12: 46 | F12: 7.6 | G12: 4481 | H12: 142 | I12: =IF($B12="","",IF(C12="","",IFERROR(ROUND(IF('دليل المؤشرات'!$D$4="↓",MIN('دليل المؤشرات'!$F$4/C12,1),IF('دليل المؤشرات'!$D$4="★",C12/10,MIN(C12/'دليل المؤشرات'!$F$4,1)))*'دليل المؤشرات'!$E$4,1),0))) -> 27.5 | J12: =IF($B12="","",IF(D12="","",IFERROR(ROUND(IF('دليل المؤشرات'!$D$5="↓",MIN('دليل المؤشرات'!$F$5/D12,1),IF('دليل المؤشرات'!$D$5="★",D12/10,MIN(D12/'دليل المؤشرات'!$F$5,1)))*'دليل المؤشرات'!$E$5,1),0))) -> 16.2 | K12: =IF($B12="","",IF(E12="","",IFERROR(ROUND(IF('دليل المؤشرات'!$D$6="↓",MIN('دليل المؤشرات'!$F$6/E12,1),IF('دليل المؤشرات'!$D$6="★",E12/10,MIN(E12/'دليل المؤشرات'!$F$6,1)))*'دليل المؤشرات'!$E$6,1),0))) -> 13.8 | L12: =IF($B12="","",IF(F12="","",IFERROR(ROUND(IF('دليل المؤشرات'!$D$7="↓",MIN('دليل المؤشرات'!$F$7/F12,1),IF('دليل المؤشرات'!$D$7="★",F12/10,MIN(F12/'دليل المؤشرات'!$F$7,1)))*'دليل المؤشرات'!$E$7,1),0))) -> 12.7 | M12: =IF($B12="","",IF(G12="","",IFERROR(ROUND(IF('دليل المؤشرات'!$D$8="↓",MIN('دليل المؤشرات'!$F$8/G12,1),IF('دليل المؤشرات'!$D$8="★",G12/10,MIN(G12/'دليل المؤشرات'!$F$8,1)))*'دليل المؤشرات'!$E$8,1),0))) -> 9 | N12: =IF($B12="","",IF(H12="","",IFERROR(ROUND(IF('دليل المؤشرات'!$D$9="↓",MIN('دليل المؤشرات'!$F$9/H12,1),IF('دليل المؤشرات'!$D$9="★",H12/10,MIN(H12/'دليل المؤشرات'!$F$9,1)))*'دليل المؤشرات'!$E$9,1),0))) -> 9.2 | O12: =IF(B12="","",ROUND(SUM(I12:N12),1)) -> 88.4 | P12: =IF(O12="","",IF(O12>=90,"أداء متميز",IF(O12>=75,"يفوق التوقعات",IF(O12>=60,"يلبّي التوقعات",IF(O12>=45,"يحتاج تطوير","غير مُرضٍ"))))) -> يفوق التوقعات
A13: 10 | B13: أمل البقمي | C13: 53133 | D13: 82 | E13: 41 | F13: 8.3 | G13: 4121 | H13: 134 | I13: =IF($B13="","",IF(C13="","",IFERROR(ROUND(IF('دليل المؤشرات'!$D$4="↓",MIN('دليل المؤشرات'!$F$4/C13,1),IF('دليل المؤشرات'!$D$4="★",C13/10,MIN(C13/'دليل المؤشرات'!$F$4,1)))*'دليل المؤشرات'!$E$4,1),0))) -> 26.6 | J13: =IF($B13="","",IF(D13="","",IFERROR(ROUND(IF('دليل المؤشرات'!$D$5="↓",MIN('دليل المؤشرات'!$F$5/D13,1),IF('دليل المؤشرات'!$D$5="★",D13/10,MIN(D13/'دليل المؤشرات'!$F$5,1)))*'دليل المؤشرات'!$E$5,1),0))) -> 18.2 | K13: =IF($B13="","",IF(E13="","",IFERROR(ROUND(IF('دليل المؤشرات'!$D$6="↓",MIN('دليل المؤشرات'!$F$6/E13,1),IF('دليل المؤشرات'!$D$6="★",E13/10,MIN(E13/'دليل المؤشرات'!$F$6,1)))*'دليل المؤشرات'!$E$6,1),0))) -> 12.3 | L13: =IF($B13="","",IF(F13="","",IFERROR(ROUND(IF('دليل المؤشرات'!$D$7="↓",MIN('دليل المؤشرات'!$F$7/F13,1),IF('دليل المؤشرات'!$D$7="★",F13/10,MIN(F13/'دليل المؤشرات'!$F$7,1)))*'دليل المؤشرات'!$E$7,1),0))) -> 13.8 | M13: =IF($B13="","",IF(G13="","",IFERROR(ROUND(IF('دليل المؤشرات'!$D$8="↓",MIN('دليل المؤشرات'!$F$8/G13,1),IF('دليل المؤشرات'!$D$8="★",G13/10,MIN(G13/'دليل المؤشرات'!$F$8,1)))*'دليل المؤشرات'!$E$8,1),0))) -> 8.2 | N13: =IF($B13="","",IF(H13="","",IFERROR(ROUND(IF('دليل المؤشرات'!$D$9="↓",MIN('دليل المؤشرات'!$F$9/H13,1),IF('دليل المؤشرات'!$D$9="★",H13/10,MIN(H13/'دليل المؤشرات'!$F$9,1)))*'دليل المؤشرات'!$E$9,1),0))) -> 8.6 | O13: =IF(B13="","",ROUND(SUM(I13:N13),1)) -> 87.7 | P13: =IF(O13="","",IF(O13>=90,"أداء متميز",IF(O13>=75,"يفوق التوقعات",IF(O13>=60,"يلبّي التوقعات",IF(O13>=45,"يحتاج تطوير","غير مُرضٍ"))))) -> يفوق التوقعات
A14: 11 | B14: وليد الشمري | C14: 44714 | D14: 63 | E14: 39 | F14: 6.4 | G14: 3319 | H14: 108 | I14: =IF($B14="","",IF(C14="","",IFERROR(ROUND(IF('دليل المؤشرات'!$D$4="↓",MIN('دليل المؤشرات'!$F$4/C14,1),IF('دليل المؤشرات'!$D$4="★",C14/10,MIN(C14/'دليل المؤشرات'!$F$4,1)))*'دليل المؤشرات'!$E$4,1),0))) -> 22.4 | J14: =IF($B14="","",IF(D14="","",IFERROR(ROUND(IF('دليل المؤشرات'!$D$5="↓",MIN('دليل المؤشرات'!$F$5/D14,1),IF('دليل المؤشرات'!$D$5="★",D14/10,MIN(D14/'دليل المؤشرات'!$F$5,1)))*'دليل المؤشرات'!$E$5,1),0))) -> 14 | K14: =IF($B14="","",IF(E14="","",IFERROR(ROUND(IF('دليل المؤشرات'!$D$6="↓",MIN('دليل المؤشرات'!$F$6/E14,1),IF('دليل المؤشرات'!$D$6="★",E14/10,MIN(E14/'دليل المؤشرات'!$F$6,1)))*'دليل المؤشرات'!$E$6,1),0))) -> 11.7 | L14: =IF($B14="","",IF(F14="","",IFERROR(ROUND(IF('دليل المؤشرات'!$D$7="↓",MIN('دليل المؤشرات'!$F$7/F14,1),IF('دليل المؤشرات'!$D$7="★",F14/10,MIN(F14/'دليل المؤشرات'!$F$7,1)))*'دليل المؤشرات'!$E$7,1),0))) -> 10.7 | M14: =IF($B14="","",IF(G14="","",IFERROR(ROUND(IF('دليل المؤشرات'!$D$8="↓",MIN('دليل المؤشرات'!$F$8/G14,1),IF('دليل المؤشرات'!$D$8="★",G14/10,MIN(G14/'دليل المؤشرات'!$F$8,1)))*'دليل المؤشرات'!$E$8,1),0))) -> 6.6 | N14: =IF($B14="","",IF(H14="","",IFERROR(ROUND(IF('دليل المؤشرات'!$D$9="↓",MIN('دليل المؤشرات'!$F$9/H14,1),IF('دليل المؤشرات'!$D$9="★",H14/10,MIN(H14/'دليل المؤشرات'!$F$9,1)))*'دليل المؤشرات'!$E$9,1),0))) -> 7 | O14: =IF(B14="","",ROUND(SUM(I14:N14),1)) -> 72.4 | P14: =IF(O14="","",IF(O14>=90,"أداء متميز",IF(O14>=75,"يفوق التوقعات",IF(O14>=60,"يلبّي التوقعات",IF(O14>=45,"يحتاج تطوير","غير مُرضٍ"))))) -> يلبّي التوقعات
A15: 12 | B15: مشعل الشمري | C15: 52617 | D15: 80 | E15: 39 | F15: 7.3 | G15: 4005 | H15: 138 | I15: =IF($B15="","",IF(C15="","",IFERROR(ROUND(IF('دليل المؤشرات'!$D$4="↓",MIN('دليل المؤشرات'!$F$4/C15,1),IF('دليل المؤشرات'!$D$4="★",C15/10,MIN(C15/'دليل المؤشرات'!$F$4,1)))*'دليل المؤشرات'!$E$4,1),0))) -> 26.3 | J15: =IF($B15="","",IF(D15="","",IFERROR(ROUND(IF('دليل المؤشرات'!$D$5="↓",MIN('دليل المؤشرات'!$F$5/D15,1),IF('دليل المؤشرات'!$D$5="★",D15/10,MIN(D15/'دليل المؤشرات'!$F$5,1)))*'دليل المؤشرات'!$E$5,1),0))) -> 17.8 | K15: =IF($B15="","",IF(E15="","",IFERROR(ROUND(IF('دليل المؤشرات'!$D$6="↓",MIN('دليل المؤشرات'!$F$6/E15,1),IF('دليل المؤشرات'!$D$6="★",E15/10,MIN(E15/'دليل المؤشرات'!$F$6,1)))*'دليل المؤشرات'!$E$6,1),0))) -> 11.7 | L15: =IF($B15="","",IF(F15="","",IFERROR(ROUND(IF('دليل المؤشرات'!$D$7="↓",MIN('دليل المؤشرات'!$F$7/F15,1),IF('دليل المؤشرات'!$D$7="★",F15/10,MIN(F15/'دليل المؤشرات'!$F$7,1)))*'دليل المؤشرات'!$E$7,1),0))) -> 12.2 | M15: =IF($B15="","",IF(G15="","",IFERROR(ROUND(IF('دليل المؤشرات'!$D$8="↓",MIN('دليل المؤشرات'!$F$8/G15,1),IF('دليل المؤشرات'!$D$8="★",G15/10,MIN(G15/'دليل المؤشرات'!$F$8,1)))*'دليل المؤشرات'!$E$8,1),0))) -> 8 | N15: =IF($B15="","",IF(H15="","",IFERROR(ROUND(IF('دليل المؤشرات'!$D$9="↓",MIN('دليل المؤشرات'!$F$9/H15,1),IF('دليل المؤشرات'!$D$9="★",H15/10,MIN(H15/'دليل المؤشرات'!$F$9,1)))*'دليل المؤشرات'!$E$9,1),0))) -> 8.9 | O15: =IF(B15="","",ROUND(SUM(I15:N15),1)) -> 84.9 | P15: =IF(O15="","",IF(O15>=90,"أداء متميز",IF(O15>=75,"يفوق التوقعات",IF(O15>=60,"يلبّي التوقعات",IF(O15>=45,"يحتاج تطوير","غير مُرضٍ"))))) -> يفوق التوقعات
... A21: 18 | B21: رزان الشهراني | C21: 46689 | D21: 68 | E21: 36 | F21: 7.4 | G21: 4094 | H21: 121 | I21: =IF($B21="","",IF(C21="","",IFERROR(ROUND(IF('دليل المؤشرات'!$D$4="↓",MIN('دليل المؤشرات'!$F$4/C21,1),IF('دليل المؤشرات'!$D$4="★",C21/10,MIN(C21/'دليل المؤشرات'!$F$4,1)))*'دليل المؤشرات'!$E$4,1),0))) -> 23.3 | J21: =IF($B21="","",IF(D21="","",IFERROR(ROUND(IF('دليل المؤشرات'!$D$5="↓",MIN('دليل المؤشرات'!$F$5/D21,1),IF('دليل المؤشرات'!$D$5="★",D21/10,MIN(D21/'دليل المؤشرات'!$F$5,1)))*'دليل المؤشرات'!$E$5,1),0))) -> 15.1 | K21: =IF($B21="","",IF(E21="","",IFERROR(ROUND(IF('دليل المؤشرات'!$D$6="↓",MIN('دليل المؤشرات'!$F$6/E21,1),IF('دليل المؤشرات'!$D$6="★",E21/10,MIN(E21/'دليل المؤشرات'!$F$6,1)))*'دليل المؤشرات'!$E$6,1),0))) -> 10.8 | L21: =IF($B21="","",IF(F21="","",IFERROR(ROUND(IF('دليل المؤشرات'!$D$7="↓",MIN('دليل المؤشرات'!$F$7/F21,1),IF('دليل المؤشرات'!$D$7="★",F21/10,MIN(F21/'دليل المؤشرات'!$F$7,1)))*'دليل المؤشرات'!$E$7,1),0))) -> 12.3 | M21: =IF($B21="","",IF(G21="","",IFERROR(ROUND(IF('دليل المؤشرات'!$D$8="↓",MIN('دليل المؤشرات'!$F$8/G21,1),IF('دليل المؤشرات'!$D$8="★",G21/10,MIN(G21/'دليل المؤشرات'!$F$8,1)))*'دليل المؤشرات'!$E$8,1),0))) -> 8.2 | N21: =IF($B21="","",IF(H21="","",IFERROR(ROUND(IF('دليل المؤشرات'!$D$9="↓",MIN('دليل المؤشرات'!$F$9/H21,1),IF('دليل المؤشرات'!$D$9="★",H21/10,MIN(H21/'دليل المؤشرات'!$F$9,1)))*'دليل المؤشرات'!$E$9,1),0))) -> 7.8 | O21: =IF(B21="","",ROUND(SUM(I21:N21),1)) -> 77.5 | P21: =IF(O21="","",IF(O21>=90,"أداء متميز",IF(O21>=75,"يفوق التوقعات",IF(O21>=60,"يلبّي التوقعات",IF(O21>=45,"يحتاج تطوير","غير مُرضٍ"))))) -> يفوق التوقعات
A22: 19 | I22: =IF($B22="","",IF(C22="","",IFERROR(ROUND(IF('دليل المؤشرات'!$D$4="↓",MIN('دليل المؤشرات'!$F$4/C22,1),IF('دليل المؤشرات'!$D$4="★",C22/10,MIN(C22/'دليل المؤشرات'!$F$4,1)))*'دليل المؤشرات'!$E$4,1),0))) | J22: =IF($B22="","",IF(D22="","",IFERROR(ROUND(IF('دليل المؤشرات'!$D$5="↓",MIN('دليل المؤشرات'!$F$5/D22,1),IF('دليل المؤشرات'!$D$5="★",D22/10,MIN(D22/'دليل المؤشرات'!$F$5,1)))*'دليل المؤشرات'!$E$5,1),0))) | K22: =IF($B22="","",IF(E22="","",IFERROR(ROUND(IF('دليل المؤشرات'!$D$6="↓",MIN('دليل المؤشرات'!$F$6/E22,1),IF('دليل المؤشرات'!$D$6="★",E22/10,MIN(E22/'دليل المؤشرات'!$F$6,1)))*'دليل المؤشرات'!$E$6,1),0))) | L22: =IF($B22="","",IF(F22="","",IFERROR(ROUND(IF('دليل المؤشرات'!$D$7="↓",MIN('دليل المؤشرات'!$F$7/F22,1),IF('دليل المؤشرات'!$D$7="★",F22/10,MIN(F22/'دليل المؤشرات'!$F$7,1)))*'دليل المؤشرات'!$E$7,1),0))) | M22: =IF($B22="","",IF(G22="","",IFERROR(ROUND(IF('دليل المؤشرات'!$D$8="↓",MIN('دليل المؤشرات'!$F$8/G22,1),IF('دليل المؤشرات'!$D$8="★",G22/10,MIN(G22/'دليل المؤشرات'!$F$8,1)))*'دليل المؤشرات'!$E$8,1),0))) | N22: =IF($B22="","",IF(H22="","",IFERROR(ROUND(IF('دليل المؤشرات'!$D$9="↓",MIN('دليل المؤشرات'!$F$9/H22,1),IF('دليل المؤشرات'!$D$9="★",H22/10,MIN(H22/'دليل المؤشرات'!$F$9,1)))*'دليل المؤشرات'!$E$9,1),0))) | O22: =IF(B22="","",ROUND(SUM(I22:N22),1)) | P22: =IF(O22="","",IF(O22>=90,"أداء متميز",IF(O22>=75,"يفوق التوقعات",IF(O22>=60,"يلبّي التوقعات",IF(O22>=45,"يحتاج تطوير","غير مُرضٍ")))))
A23: 20 | I23: =IF($B23="","",IF(C23="","",IFERROR(ROUND(IF('دليل المؤشرات'!$D$4="↓",MIN('دليل المؤشرات'!$F$4/C23,1),IF('دليل المؤشرات'!$D$4="★",C23/10,MIN(C23/'دليل المؤشرات'!$F$4,1)))*'دليل المؤشرات'!$E$4,1),0))) | J23: =IF($B23="","",IF(D23="","",IFERROR(ROUND(IF('دليل المؤشرات'!$D$5="↓",MIN('دليل المؤشرات'!$F$5/D23,1),IF('دليل المؤشرات'!$D$5="★",D23/10,MIN(D23/'دليل المؤشرات'!$F$5,1)))*'دليل المؤشرات'!$E$5,1),0))) | K23: =IF($B23="","",IF(E23="","",IFERROR(ROUND(IF('دليل المؤشرات'!$D$6="↓",MIN('دليل المؤشرات'!$F$6/E23,1),IF('دليل المؤشرات'!$D$6="★",E23/10,MIN(E23/'دليل المؤشرات'!$F$6,1)))*'دليل المؤشرات'!$E$6,1),0))) | L23: =IF($B23="","",IF(F23="","",IFERROR(ROUND(IF('دليل المؤشرات'!$D$7="↓",MIN('دليل المؤشرات'!$F$7/F23,1),IF('دليل المؤشرات'!$D$7="★",F23/10,MIN(F23/'دليل المؤشرات'!$F$7,1)))*'دليل المؤشرات'!$E$7,1),0))) | M23: =IF($B23="","",IF(G23="","",IFERROR(ROUND(IF('دليل المؤشرات'!$D$8="↓",MIN('دليل المؤشرات'!$F$8/G23,1),IF('دليل المؤشرات'!$D$8="★",G23/10,MIN(G23/'دليل المؤشرات'!$F$8,1)))*'دليل المؤشرات'!$E$8,1),0))) | N23: =IF($B23="","",IF(H23="","",IFERROR(ROUND(IF('دليل المؤشرات'!$D$9="↓",MIN('دليل المؤشرات'!$F$9/H23,1),IF('دليل المؤشرات'!$D$9="★",H23/10,MIN(H23/'دليل المؤشرات'!$F$9,1)))*'دليل المؤشرات'!$E$9,1),0))) | O23: =IF(B23="","",ROUND(SUM(I23:N23),1)) | P23: =IF(O23="","",IF(O23>=90,"أداء متميز",IF(O23>=75,"يفوق التوقعات",IF(O23>=60,"يلبّي التوقعات",IF(O23>=45,"يحتاج تطوير","غير مُرضٍ")))))
A24: 21 | I24: =IF($B24="","",IF(C24="","",IFERROR(ROUND(IF('دليل المؤشرات'!$D$4="↓",MIN('دليل المؤشرات'!$F$4/C24,1),IF('دليل المؤشرات'!$D$4="★",C24/10,MIN(C24/'دليل المؤشرات'!$F$4,1)))*'دليل المؤشرات'!$E$4,1),0))) | J24: =IF($B24="","",IF(D24="","",IFERROR(ROUND(IF('دليل المؤشرات'!$D$5="↓",MIN('دليل المؤشرات'!$F$5/D24,1),IF('دليل المؤشرات'!$D$5="★",D24/10,MIN(D24/'دليل المؤشرات'!$F$5,1)))*'دليل المؤشرات'!$E$5,1),0))) | K24: =IF($B24="","",IF(E24="","",IFERROR(ROUND(IF('دليل المؤشرات'!$D$6="↓",MIN('دليل المؤشرات'!$F$6/E24,1),IF('دليل المؤشرات'!$D$6="★",E24/10,MIN(E24/'دليل المؤشرات'!$F$6,1)))*'دليل المؤشرات'!$E$6,1),0))) | L24: =IF($B24="","",IF(F24="","",IFERROR(ROUND(IF('دليل المؤشرات'!$D$7="↓",MIN('دليل المؤشرات'!$F$7/F24,1),IF('دليل المؤشرات'!$D$7="★",F24/10,MIN(F24/'دليل المؤشرات'!$F$7,1)))*'دليل المؤشرات'!$E$7,1),0))) | M24: =IF($B24="","",IF(G24="","",IFERROR(ROUND(IF('دليل المؤشرات'!$D$8="↓",MIN('دليل المؤشرات'!$F$8/G24,1),IF('دليل المؤشرات'!$D$8="★",G24/10,MIN(G24/'دليل المؤشرات'!$F$8,1)))*'دليل المؤشرات'!$E$8,1),0))) | N24: =IF($B24="","",IF(H24="","",IFERROR(ROUND(IF('دليل المؤشرات'!$D$9="↓",MIN('دليل المؤشرات'!$F$9/H24,1),IF('دليل المؤشرات'!$D$9="★",H24/10,MIN(H24/'دليل المؤشرات'!$F$9,1)))*'دليل المؤشرات'!$E$9,1),0))) | O24: =IF(B24="","",ROUND(SUM(I24:N24),1)) | P24: =IF(O24="","",IF(O24>=90,"أداء متميز",IF(O24>=75,"يفوق التوقعات",IF(O24>=60,"يلبّي التوقعات",IF(O24>=45,"يحتاج تطوير","غير مُرضٍ")))))
A25: 22 | I25: =IF($B25="","",IF(C25="","",IFERROR(ROUND(IF('دليل المؤشرات'!$D$4="↓",MIN('دليل المؤشرات'!$F$4/C25,1),IF('دليل المؤشرات'!$D$4="★",C25/10,MIN(C25/'دليل المؤشرات'!$F$4,1)))*'دليل المؤشرات'!$E$4,1),0))) | J25: =IF($B25="","",IF(D25="","",IFERROR(ROUND(IF('دليل المؤشرات'!$D$5="↓",MIN('دليل المؤشرات'!$F$5/D25,1),IF('دليل المؤشرات'!$D$5="★",D25/10,MIN(D25/'دليل المؤشرات'!$F$5,1)))*'دليل المؤشرات'!$E$5,1),0))) | K25: =IF($B25="","",IF(E25="","",IFERROR(ROUND(IF('دليل المؤشرات'!$D$6="↓",MIN('دليل المؤشرات'!$F$6/E25,1),IF('دليل المؤشرات'!$D$6="★",E25/10,MIN(E25/'دليل المؤشرات'!$F$6,1)))*'دليل المؤشرات'!$E$6,1),0))) | L25: =IF($B25="","",IF(F25="","",IFERROR(ROUND(IF('دليل المؤشرات'!$D$7="↓",MIN('دليل المؤشرات'!$F$7/F25,1),IF('دليل المؤشرات'!$D$7="★",F25/10,MIN(F25/'دليل المؤشرات'!$F$7,1)))*'دليل المؤشرات'!$E$7,1),0))) | M25: =IF($B25="","",IF(G25="","",IFERROR(ROUND(IF('دليل المؤشرات'!$D$8="↓",MIN('دليل المؤشرات'!$F$8/G25,1),IF('دليل المؤشرات'!$D$8="★",G25/10,MIN(G25/'دليل المؤشرات'!$F$8,1)))*'دليل المؤشرات'!$E$8,1),0))) | N25: =IF($B25="","",IF(H25="","",IFERROR(ROUND(IF('دليل المؤشرات'!$D$9="↓",MIN('دليل المؤشرات'!$F$9/H25,1),IF('دليل المؤشرات'!$D$9="★",H25/10,MIN(H25/'دليل المؤشرات'!$F$9,1)))*'دليل المؤشرات'!$E$9,1),0))) | O25: =IF(B25="","",ROUND(SUM(I25:N25),1)) | P25: =IF(O25="","",IF(O25>=90,"أداء متميز",IF(O25>=75,"يفوق التوقعات",IF(O25>=60,"يلبّي التوقعات",IF(O25>=45,"يحتاج تطوير","غير مُرضٍ")))))
A26: 23 | I26: =IF($B26="","",IF(C26="","",IFERROR(ROUND(IF('دليل المؤشرات'!$D$4="↓",MIN('دليل المؤشرات'!$F$4/C26,1),IF('دليل المؤشرات'!$D$4="★",C26/10,MIN(C26/'دليل المؤشرات'!$F$4,1)))*'دليل المؤشرات'!$E$4,1),0))) | J26: =IF($B26="","",IF(D26="","",IFERROR(ROUND(IF('دليل المؤشرات'!$D$5="↓",MIN('دليل المؤشرات'!$F$5/D26,1),IF('دليل المؤشرات'!$D$5="★",D26/10,MIN(D26/'دليل المؤشرات'!$F$5,1)))*'دليل المؤشرات'!$E$5,1),0))) | K26: =IF($B26="","",IF(E26="","",IFERROR(ROUND(IF('دليل المؤشرات'!$D$6="↓",MIN('دليل المؤشرات'!$F$6/E26,1),IF('دليل المؤشرات'!$D$6="★",E26/10,MIN(E26/'دليل المؤشرات'!$F$6,1)))*'دليل المؤشرات'!$E$6,1),0))) | L26: =IF($B26="","",IF(F26="","",IFERROR(ROUND(IF('دليل المؤشرات'!$D$7="↓",MIN('دليل المؤشرات'!$F$7/F26,1),IF('دليل المؤشرات'!$D$7="★",F26/10,MIN(F26/'دليل المؤشرات'!$F$7,1)))*'دليل المؤشرات'!$E$7,1),0))) | M26: =IF($B26="","",IF(G26="","",IFERROR(ROUND(IF('دليل المؤشرات'!$D$8="↓",MIN('دليل المؤشرات'!$F$8/G26,1),IF('دليل المؤشرات'!$D$8="★",G26/10,MIN(G26/'دليل المؤشرات'!$F$8,1)))*'دليل المؤشرات'!$E$8,1),0))) | N26: =IF($B26="","",IF(H26="","",IFERROR(ROUND(IF('دليل المؤشرات'!$D$9="↓",MIN('دليل المؤشرات'!$F$9/H26,1),IF('دليل المؤشرات'!$D$9="★",H26/10,MIN(H26/'دليل المؤشرات'!$F$9,1)))*'دليل المؤشرات'!$E$9,1),0))) | O26: =IF(B26="","",ROUND(SUM(I26:N26),1)) | P26: =IF(O26="","",IF(O26>=90,"أداء متميز",IF(O26>=75,"يفوق التوقعات",IF(O26>=60,"يلبّي التوقعات",IF(O26>=45,"يحتاج تطوير","غير مُرضٍ")))))
A27: 24 | I27: =IF($B27="","",IF(C27="","",IFERROR(ROUND(IF('دليل المؤشرات'!$D$4="↓",MIN('دليل المؤشرات'!$F$4/C27,1),IF('دليل المؤشرات'!$D$4="★",C27/10,MIN(C27/'دليل المؤشرات'!$F$4,1)))*'دليل المؤشرات'!$E$4,1),0))) | J27: =IF($B27="","",IF(D27="","",IFERROR(ROUND(IF('دليل المؤشرات'!$D$5="↓",MIN('دليل المؤشرات'!$F$5/D27,1),IF('دليل المؤشرات'!$D$5="★",D27/10,MIN(D27/'دليل المؤشرات'!$F$5,1)))*'دليل المؤشرات'!$E$5,1),0))) | K27: =IF($B27="","",IF(E27="","",IFERROR(ROUND(IF('دليل المؤشرات'!$D$6="↓",MIN('دليل المؤشرات'!$F$6/E27,1),IF('دليل المؤشرات'!$D$6="★",E27/10,MIN(E27/'دليل المؤشرات'!$F$6,1)))*'دليل المؤشرات'!$E$6,1),0))) | L27: =IF($B27="","",IF(F27="","",IFERROR(ROUND(IF('دليل المؤشرات'!$D$7="↓",MIN('دليل المؤشرات'!$F$7/F27,1),IF('دليل المؤشرات'!$D$7="★",F27/10,MIN(F27/'دليل المؤشرات'!$F$7,1)))*'دليل المؤشرات'!$E$7,1),0))) | M27: =IF($B27="","",IF(G27="","",IFERROR(ROUND(IF('دليل المؤشرات'!$D$8="↓",MIN('دليل المؤشرات'!$F$8/G27,1),IF('دليل المؤشرات'!$D$8="★",G27/10,MIN(G27/'دليل المؤشرات'!$F$8,1)))*'دليل المؤشرات'!$E$8,1),0))) | N27: =IF($B27="","",IF(H27="","",IFERROR(ROUND(IF('دليل المؤشرات'!$D$9="↓",MIN('دليل المؤشرات'!$F$9/H27,1),IF('دليل المؤشرات'!$D$9="★",H27/10,MIN(H27/'دليل المؤشرات'!$F$9,1)))*'دليل المؤشرات'!$E$9,1),0))) | O27: =IF(B27="","",ROUND(SUM(I27:N27),1)) | P27: =IF(O27="","",IF(O27>=90,"أداء متميز",IF(O27>=75,"يفوق التوقعات",IF(O27>=60,"يلبّي التوقعات",IF(O27>=45,"يحتاج تطوير","غير مُرضٍ")))))
A28: 25 | I28: =IF($B28="","",IF(C28="","",IFERROR(ROUND(IF('دليل المؤشرات'!$D$4="↓",MIN('دليل المؤشرات'!$F$4/C28,1),IF('دليل المؤشرات'!$D$4="★",C28/10,MIN(C28/'دليل المؤشرات'!$F$4,1)))*'دليل المؤشرات'!$E$4,1),0))) | J28: =IF($B28="","",IF(D28="","",IFERROR(ROUND(IF('دليل المؤشرات'!$D$5="↓",MIN('دليل المؤشرات'!$F$5/D28,1),IF('دليل المؤشرات'!$D$5="★",D28/10,MIN(D28/'دليل المؤشرات'!$F$5,1)))*'دليل المؤشرات'!$E$5,1),0))) | K28: =IF($B28="","",IF(E28="","",IFERROR(ROUND(IF('دليل المؤشرات'!$D$6="↓",MIN('دليل المؤشرات'!$F$6/E28,1),IF('دليل المؤشرات'!$D$6="★",E28/10,MIN(E28/'دليل المؤشرات'!$F$6,1)))*'دليل المؤشرات'!$E$6,1),0))) | L28: =IF($B28="","",IF(F28="","",IFERROR(ROUND(IF('دليل المؤشرات'!$D$7="↓",MIN('دليل المؤشرات'!$F$7/F28,1),IF('دليل المؤشرات'!$D$7="★",F28/10,MIN(F28/'دليل المؤشرات'!$F$7,1)))*'دليل المؤشرات'!$E$7,1),0))) | M28: =IF($B28="","",IF(G28="","",IFERROR(ROUND(IF('دليل المؤشرات'!$D$8="↓",MIN('دليل المؤشرات'!$F$8/G28,1),IF('دليل المؤشرات'!$D$8="★",G28/10,MIN(G28/'دليل المؤشرات'!$F$8,1)))*'دليل المؤشرات'!$E$8,1),0))) | N28: =IF($B28="","",IF(H28="","",IFERROR(ROUND(IF('دليل المؤشرات'!$D$9="↓",MIN('دليل المؤشرات'!$F$9/H28,1),IF('دليل المؤشرات'!$D$9="★",H28/10,MIN(H28/'دليل المؤشرات'!$F$9,1)))*'دليل المؤشرات'!$E$9,1),0))) | O28: =IF(B28="","",ROUND(SUM(I28:N28),1)) | P28: =IF(O28="","",IF(O28>=90,"أداء متميز",IF(O28>=75,"يفوق التوقعات",IF(O28>=60,"يلبّي التوقعات",IF(O28>=45,"يحتاج تطوير","غير مُرضٍ")))))
B30: متوسط القسم (يتجاهل الصفوف الفارغة) | O30: =IFERROR(ROUND(AVERAGE(O4:O28),1),0) -> 80.4 | P30: =COUNTA(B4:B28)&" موظف" -> 18 موظف

Sheet استقطاب المواهب
A1: بطاقة مؤشرات الأداء — استقطاب المواهب والتوظيف | المجموع 100 نقطة · صفر على الحضور
A2: # | B2: اسم الموظف | C2: جودة التوظيف % اجتياز التجربة | D2: زمن شغل الوظيفة (يوم) | E2: عدد التعيينات المكتملة | F2: نسبة قبول العروض % | G2: تكلفة التوظيف (ر.س) | H2: رضا المدير الطالب (1-10) | I2: د1 | J2: د2 | K2: د3 | L2: د4 | M2: د5 | N2: د6 | O2: الإجمالي | P2: النتيجة
B3: الهدف ← | → الوزن | C3: ='دليل المؤشرات'!F11 -> 90 | D3: ='دليل المؤشرات'!F12 -> 30 | E3: ='دليل المؤشرات'!F13 -> 8 | F3: ='دليل المؤشرات'!F14 -> 80 | G3: ='دليل المؤشرات'!F15 -> 4000 | H3: ='دليل المؤشرات'!F16 -> 10 | I3: ='دليل المؤشرات'!E11 -> 25 | J3: ='دليل المؤشرات'!E12 -> 20 | K3: ='دليل المؤشرات'!E13 -> 15 | L3: ='دليل المؤشرات'!E14 -> 15 | M3: ='دليل المؤشرات'!E15 -> 15 | N3: ='دليل المؤشرات'!E16 -> 10 | O3: 100
A4: 1 | B4: نواف الشهري | C4: 62 | D4: 40.4 | E4: 5.3 | F4: 52 | G4: 5784 | H4: 7 | I4: =IF($B4="","",IF(C4="","",IFERROR(ROUND(IF('دليل المؤشرات'!$D$11="↓",MIN('دليل المؤشرات'!$F$11/C4,1),IF('دليل المؤشرات'!$D$11="★",C4/10,MIN(C4/'دليل المؤشرات'!$F$11,1)))*'دليل المؤشرات'!$E$11,1),0))) -> 17.2 | J4: =IF($B4="","",IF(D4="","",IFERROR(ROUND(IF('دليل المؤشرات'!$D$12="↓",MIN('دليل المؤشرات'!$F$12/D4,1),IF('دليل المؤشرات'!$D$12="★",D4/10,MIN(D4/'دليل المؤشرات'!$F$12,1)))*'دليل المؤشرات'!$E$12,1),0))) -> 14.9 | K4: =IF($B4="","",IF(E4="","",IFERROR(ROUND(IF('دليل المؤشرات'!$D$13="↓",MIN('دليل المؤشرات'!$F$13/E4,1),IF('دليل المؤشرات'!$D$13="★",E4/10,MIN(E4/'دليل المؤشرات'!$F$13,1)))*'دليل المؤشرات'!$E$13,1),0))) -> 9.9 | L4: =IF($B4="","",IF(F4="","",IFERROR(ROUND(IF('دليل المؤشرات'!$D$14="↓",MIN('دليل المؤشرات'!$F$14/F4,1),IF('دليل المؤشرات'!$D$14="★",F4/10,MIN(F4/'دليل المؤشرات'!$F$14,1)))*'دليل المؤشرات'!$E$14,1),0))) -> 9.8 | M4: =IF($B4="","",IF(G4="","",IFERROR(ROUND(IF('دليل المؤشرات'!$D$15="↓",MIN('دليل المؤشرات'!$F$15/G4,1),IF('دليل المؤشرات'!$D$15="★",G4/10,MIN(G4/'دليل المؤشرات'!$F$15,1)))*'دليل المؤشرات'!$E$15,1),0))) -> 10.4 | N4: =IF($B4="","",IF(H4="","",IFERROR(ROUND(IF('دليل المؤشرات'!$D$16="↓",MIN('دليل المؤشرات'!$F$16/H4,1),IF('دليل المؤشرات'!$D$16="★",H4/10,MIN(H4/'دليل المؤشرات'!$F$16,1)))*'دليل المؤشرات'!$E$16,1),0))) -> 7 | O4: =IF(B4="","",ROUND(SUM(I4:N4),1)) -> 69.2 | P4: =IF(O4="","",IF(O4>=90,"أداء متميز",IF(O4>=75,"يفوق التوقعات",IF(O4>=60,"يلبّي التوقعات",IF(O4>=45,"يحتاج تطوير","غير مُرضٍ"))))) -> يلبّي التوقعات
A5: 2 | B5: يزيد المالكي | C5: 65 | D5: 42.1 | E5: 5.1 | F5: 55 | G5: 6056 | H5: 6 | I5: =IF($B5="","",IF(C5="","",IFERROR(ROUND(IF('دليل المؤشرات'!$D$11="↓",MIN('دليل المؤشرات'!$F$11/C5,1),IF('دليل المؤشرات'!$D$11="★",C5/10,MIN(C5/'دليل المؤشرات'!$F$11,1)))*'دليل المؤشرات'!$E$11,1),0))) -> 18.1 | J5: =IF($B5="","",IF(D5="","",IFERROR(ROUND(IF('دليل المؤشرات'!$D$12="↓",MIN('دليل المؤشرات'!$F$12/D5,1),IF('دليل المؤشرات'!$D$12="★",D5/10,MIN(D5/'دليل المؤشرات'!$F$12,1)))*'دليل المؤشرات'!$E$12,1),0))) -> 14.3 | K5: =IF($B5="","",IF(E5="","",IFERROR(ROUND(IF('دليل المؤشرات'!$D$13="↓",MIN('دليل المؤشرات'!$F$13/E5,1),IF('دليل المؤشرات'!$D$13="★",E5/10,MIN(E5/'دليل المؤشرات'!$F$13,1)))*'دليل المؤشرات'!$E$13,1),0))) -> 9.6 | L5: =IF($B5="","",IF(F5="","",IFERROR(ROUND(IF('دليل المؤشرات'!$D$14="↓",MIN('دليل المؤشرات'!$F$14/F5,1),IF('دليل المؤشرات'!$D$14="★",F5/10,MIN(F5/'دليل المؤشرات'!$F$14,1)))*'دليل المؤشرات'!$E$14,1),0))) -> 10.3 | M5: =IF($B5="","",IF(G5="","",IFERROR(ROUND(IF('دليل المؤشرات'!$D$15="↓",MIN('دليل المؤشرات'!$F$15/G5,1),IF('دليل المؤشرات'!$D$15="★",G5/10,MIN(G5/'دليل المؤشرات'!$F$15,1)))*'دليل المؤشرات'!$E$15,1),0))) -> 9.9 | N5: =IF($B5="","",IF(H5="","",IFERROR(ROUND(IF('دليل المؤشرات'!$D$16="↓",MIN('دليل المؤشرات'!$F$16/H5,1),IF('دليل المؤشرات'!$D$16="★",H5/10,MIN(H5/'دليل المؤشرات'!$F$16,1)))*'دليل المؤشرات'!$E$16,1),0))) -> 6 | O5: =IF(B5="","",ROUND(SUM(I5:N5),1)) -> 68.2 | P5: =IF(O5="","",IF(O5>=90,"أداء متميز",IF(O5>=75,"يفوق التوقعات",IF(O5>=60,"يلبّي التوقعات",IF(O5>=45,"يحتاج تطوير","غير مُرضٍ"))))) -> يلبّي التوقعات
A6: 3 | B6: محمد الشهري | C6: 59 | D6: 48.5 | E6: 5.4 | F6: 51 | G6: 5722 | H6: 7 | I6: =IF($B6="","",IF(C6="","",IFERROR(ROUND(IF('دليل المؤشرات'!$D$11="↓",MIN('دليل المؤشرات'!$F$11/C6,1),IF('دليل المؤشرات'!$D$11="★",C6/10,MIN(C6/'دليل المؤشرات'!$F$11,1)))*'دليل المؤشرات'!$E$11,1),0))) -> 16.4 | J6: =IF($B6="","",IF(D6="","",IFERROR(ROUND(IF('دليل المؤشرات'!$D$12="↓",MIN('دليل المؤشرات'!$F$12/D6,1),IF('دليل المؤشرات'!$D$12="★",D6/10,MIN(D6/'دليل المؤشرات'!$F$12,1)))*'دليل المؤشرات'!$E$12,1),0))) -> 12.4 | K6: =IF($B6="","",IF(E6="","",IFERROR(ROUND(IF('دليل المؤشرات'!$D$13="↓",MIN('دليل المؤشرات'!$F$13/E6,1),IF('دليل المؤشرات'!$D$13="★",E6/10,MIN(E6/'دليل المؤشرات'!$F$13,1)))*'دليل المؤشرات'!$E$13,1),0))) -> 10.1 | L6: =IF($B6="","",IF(F6="","",IFERROR(ROUND(IF('دليل المؤشرات'!$D$14="↓",MIN('دليل المؤشرات'!$F$14/F6,1),IF('دليل المؤشرات'!$D$14="★",F6/10,MIN(F6/'دليل المؤشرات'!$F$14,1)))*'دليل المؤشرات'!$E$14,1),0))) -> 9.6 | M6: =IF($B6="","",IF(G6="","",IFERROR(ROUND(IF('دليل المؤشرات'!$D$15="↓",MIN('دليل المؤشرات'!$F$15/G6,1),IF('دليل المؤشرات'!$D$15="★",G6/10,MIN(G6/'دليل المؤشرات'!$F$15,1)))*'دليل المؤشرات'!$E$15,1),0))) -> 10.5 | N6: =IF($B6="","",IF(H6="","",IFERROR(ROUND(IF('دليل المؤشرات'!$D$16="↓",MIN('دليل المؤشرات'!$F$16/H6,1),IF('دليل المؤشرات'!$D$16="★",H6/10,MIN(H6/'دليل المؤشرات'!$F$16,1)))*'دليل المؤشرات'!$E$16,1),0))) -> 7 | O6: =IF(B6="","",ROUND(SUM(I6:N6),1)) -> 66 | P6: =IF(O6="","",IF(O6>=90,"أداء متميز",IF(O6>=75,"يفوق التوقعات",IF(O6>=60,"يلبّي التوقعات",IF(O6>=45,"يحتاج تطوير","غير مُرضٍ"))))) -> يلبّي التوقعات
A7: 4 | B7: نواف المالكي | C7: 48 | D7: 52.6 | E7: 4.4 | F7: 46 | G7: 6350 | H7: 6 | I7: =IF($B7="","",IF(C7="","",IFERROR(ROUND(IF('دليل المؤشرات'!$D$11="↓",MIN('دليل المؤشرات'!$F$11/C7,1),IF('دليل المؤشرات'!$D$11="★",C7/10,MIN(C7/'دليل المؤشرات'!$F$11,1)))*'دليل المؤشرات'!$E$11,1),0))) -> 13.3 | J7: =IF($B7="","",IF(D7="","",IFERROR(ROUND(IF('دليل المؤشرات'!$D$12="↓",MIN('دليل المؤشرات'!$F$12/D7,1),IF('دليل المؤشرات'!$D$12="★",D7/10,MIN(D7/'دليل المؤشرات'!$F$12,1)))*'دليل المؤشرات'!$E$12,1),0))) -> 11.4 | K7: =IF($B7="","",IF(E7="","",IFERROR(ROUND(IF('دليل المؤشرات'!$D$13="↓",MIN('دليل المؤشرات'!$F$13/E7,1),IF('دليل المؤشرات'!$D$13="★",E7/10,MIN(E7/'دليل المؤشرات'!$F$13,1)))*'دليل المؤشرات'!$E$13,1),0))) -> 8.3 | L7: =IF($B7="","",IF(F7="","",IFERROR(ROUND(IF('دليل المؤشرات'!$D$14="↓",MIN('دليل المؤشرات'!$F$14/F7,1),IF('دليل المؤشرات'!$D$14="★",F7/10,MIN(F7/'دليل المؤشرات'!$F$14,1)))*'دليل المؤشرات'!$E$14,1),0))) -> 8.6 | M7: =IF($B7="","",IF(G7="","",IFERROR(ROUND(IF('دليل المؤشرات'!$D$15="↓",MIN('دليل المؤشرات'!$F$15/G7,1),IF('دليل المؤشرات'!$D$15="★",G7/10,MIN(G7/'دليل المؤشرات'!$F$15,1)))*'دليل المؤشرات'!$E$15,1),0))) -> 9.4 | N7: =IF($B7="","",IF(H7="","",IFERROR(ROUND(IF('دليل المؤشرات'!$D$16="↓",MIN('دليل المؤشرات'!$F$16/H7,1),IF('دليل المؤشرات'!$D$16="★",H7/10,MIN(H7/'دليل المؤشرات'!$F$16,1)))*'دليل المؤشرات'!$E$16,1),0))) -> 6 | O7: =IF(B7="","",ROUND(SUM(I7:N7),1)) -> 57 | P7: =IF(O7="","",IF(O7>=90,"أداء متميز",IF(O7>=75,"يفوق التوقعات",IF(O7>=60,"يلبّي التوقعات",IF(O7>=45,"يحتاج تطوير","غير مُرضٍ"))))) -> يحتاج تطوير
A8: 5 | B8: عبدالله العنزي | C8: 102 | D8: 29.6 | E8: 8.6 | F8: 89 | G8: 4143 | H8: 10 | I8: =IF($B8="","",IF(C8="","",IFERROR(ROUND(IF('دليل المؤشرات'!$D$11="↓",MIN('دليل المؤشرات'!$F$11/C8,1),IF('دليل المؤشرات'!$D$11="★",C8/10,MIN(C8/'دليل المؤشرات'!$F$11,1)))*'دليل المؤشرات'!$E$11,1),0))) -> 25 | J8: =IF($B8="","",IF(D8="","",IFERROR(ROUND(IF('دليل المؤشرات'!$D$12="↓",MIN('دليل المؤشرات'!$F$12/D8,1),IF('دليل المؤشرات'!$D$12="★",D8/10,MIN(D8/'دليل المؤشرات'!$F$12,1)))*'دليل المؤشرات'!$E$12,1),0))) -> 20 | K8: =IF($B8="","",IF(E8="","",IFERROR(ROUND(IF('دليل المؤشرات'!$D$13="↓",MIN('دليل المؤشرات'!$F$13/E8,1),IF('دليل المؤشرات'!$D$13="★",E8/10,MIN(E8/'دليل المؤشرات'!$F$13,1)))*'دليل المؤشرات'!$E$13,1),0))) -> 15 | L8: =IF($B8="","",IF(F8="","",IFERROR(ROUND(IF('دليل المؤشرات'!$D$14="↓",MIN('دليل المؤشرات'!$F$14/F8,1),IF('دليل المؤشرات'!$D$14="★",F8/10,MIN(F8/'دليل المؤشرات'!$F$14,1)))*'دليل المؤشرات'!$E$14,1),0))) -> 15 | M8: =IF($B8="","",IF(G8="","",IFERROR(ROUND(IF('دليل المؤشرات'!$D$15="↓",MIN('دليل المؤشرات'!$F$15/G8,1),IF('دليل المؤشرات'!$D$15="★",G8/10,MIN(G8/'دليل المؤشرات'!$F$15,1)))*'دليل المؤشرات'!$E$15,1),0))) -> 14.5 | N8: =IF($B8="","",IF(H8="","",IFERROR(ROUND(IF('دليل المؤشرات'!$D$16="↓",MIN('دليل المؤشرات'!$F$16/H8,1),IF('دليل المؤشرات'!$D$16="★",H8/10,MIN(H8/'دليل المؤشرات'!$F$16,1)))*'دليل المؤشرات'!$E$16,1),0))) -> 10 | O8: =IF(B8="","",ROUND(SUM(I8:N8),1)) -> 99.5 | P8: =IF(O8="","",IF(O8>=90,"أداء متميز",IF(O8>=75,"يفوق التوقعات",IF(O8>=60,"يلبّي التوقعات",IF(O8>=45,"يحتاج تطوير","غير مُرضٍ"))))) -> أداء متميز
A9: 6 | B9: ريان الرشيدي | C9: 76 | D9: 39 | E9: 6.7 | F9: 70 | G9: 5137 | H9: 8 | I9: =IF($B9="","",IF(C9="","",IFERROR(ROUND(IF('دليل المؤشرات'!$D$11="↓",MIN('دليل المؤشرات'!$F$11/C9,1),IF('دليل المؤشرات'!$D$11="★",C9/10,MIN(C9/'دليل المؤشرات'!$F$11,1)))*'دليل المؤشرات'!$E$11,1),0))) -> 21.1 | J9: =IF($B9="","",IF(D9="","",IFERROR(ROUND(IF('دليل المؤشرات'!$D$12="↓",MIN('دليل المؤشرات'!$F$12/D9,1),IF('دليل المؤشرات'!$D$12="★",D9/10,MIN(D9/'دليل المؤشرات'!$F$12,1)))*'دليل المؤشرات'!$E$12,1),0))) -> 15.4 | K9: =IF($B9="","",IF(E9="","",IFERROR(ROUND(IF('دليل المؤشرات'!$D$13="↓",MIN('دليل المؤشرات'!$F$13/E9,1),IF('دليل المؤشرات'!$D$13="★",E9/10,MIN(E9/'دليل المؤشرات'!$F$13,1)))*'دليل المؤشرات'!$E$13,1),0))) -> 12.6 | L9: =IF($B9="","",IF(F9="","",IFERROR(ROUND(IF('دليل المؤشرات'!$D$14="↓",MIN('دليل المؤشرات'!$F$14/F9,1),IF('دليل المؤشرات'!$D$14="★",F9/10,MIN(F9/'دليل المؤشرات'!$F$14,1)))*'دليل المؤشرات'!$E$14,1),0))) -> 13.1 | M9: =IF($B9="","",IF(G9="","",IFERROR(ROUND(IF('دليل المؤشرات'!$D$15="↓",MIN('دليل المؤشرات'!$F$15/G9,1),IF('دليل المؤشرات'!$D$15="★",G9/10,MIN(G9/'دليل المؤشرات'!$F$15,1)))*'دليل المؤشرات'!$E$15,1),0))) -> 11.7 | N9: =IF($B9="","",IF(H9="","",IFERROR(ROUND(IF('دليل المؤشرات'!$D$16="↓",MIN('دليل المؤشرات'!$F$16/H9,1),IF('دليل المؤشرات'!$D$16="★",H9/10,MIN(H9/'دليل المؤشرات'!$F$16,1)))*'دليل المؤشرات'!$E$16,1),0))) -> 8 | O9: =IF(B9="","",ROUND(SUM(I9:N9),1)) -> 81.9 | P9: =IF(O9="","",IF(O9>=90,"أداء متميز",IF(O9>=75,"يفوق التوقعات",IF(O9>=60,"يلبّي التوقعات",IF(O9>=45,"يحتاج تطوير","غير مُرضٍ"))))) -> يفوق التوقعات
A10: 7 | B10: نواف الحربي | C10: 60 | D10: 45 | E10: 5.4 | F10: 62 | G10: 5237 | H10: 7 | I10: =IF($B10="","",IF(C10="","",IFERROR(ROUND(IF('دليل المؤشرات'!$D$11="↓",MIN('دليل المؤشرات'!$F$11/C10,1),IF('دليل المؤشرات'!$D$11="★",C10/10,MIN(C10/'دليل المؤشرات'!$F$11,1)))*'دليل المؤشرات'!$E$11,1),0))) -> 16.7 | J10: =IF($B10="","",IF(D10="","",IFERROR(ROUND(IF('دليل المؤشرات'!$D$12="↓",MIN('دليل المؤشرات'!$F$12/D10,1),IF('دليل المؤشرات'!$D$12="★",D10/10,MIN(D10/'دليل المؤشرات'!$F$12,1)))*'دليل المؤشرات'!$E$12,1),0))) -> 13.3 | K10: =IF($B10="","",IF(E10="","",IFERROR(ROUND(IF('دليل المؤشرات'!$D$13="↓",MIN('دليل المؤشرات'!$F$13/E10,1),IF('دليل المؤشرات'!$D$13="★",E10/10,MIN(E10/'دليل المؤشرات'!$F$13,1)))*'دليل المؤشرات'!$E$13,1),0))) -> 10.1 | L10: =IF($B10="","",IF(F10="","",IFERROR(ROUND(IF('دليل المؤشرات'!$D$14="↓",MIN('دليل المؤشرات'!$F$14/F10,1),IF('دليل المؤشرات'!$D$14="★",F10/10,MIN(F10/'دليل المؤشرات'!$F$14,1)))*'دليل المؤشرات'!$E$14,1),0))) -> 11.6 | M10: =IF($B10="","",IF(G10="","",IFERROR(ROUND(IF('دليل المؤشرات'!$D$15="↓",MIN('دليل المؤشرات'!$F$15/G10,1),IF('دليل المؤشرات'!$D$15="★",G10/10,MIN(G10/'دليل المؤشرات'!$F$15,1)))*'دليل المؤشرات'!$E$15,1),0))) -> 11.5 | N10: =IF($B10="","",IF(H10="","",IFERROR(ROUND(IF('دليل المؤشرات'!$D$16="↓",MIN('دليل المؤشرات'!$F$16/H10,1),IF('دليل المؤشرات'!$D$16="★",H10/10,MIN(H10/'دليل المؤشرات'!$F$16,1)))*'دليل المؤشرات'!$E$16,1),0))) -> 7 | O10: =IF(B10="","",ROUND(SUM(I10:N10),1)) -> 70.2 | P10: =IF(O10="","",IF(O10>=90,"أداء متميز",IF(O10>=75,"يفوق التوقعات",IF(O10>=60,"يلبّي التوقعات",IF(O10>=45,"يحتاج تطوير","غير مُرضٍ"))))) -> يلبّي التوقعات
A11: 8 | B11: ريم الشمري | C11: 93 | D11: 31.7 | E11: 7.4 | F11: 89 | G11: 3804 | H11: 10 | I11: =IF($B11="","",IF(C11="","",IFERROR(ROUND(IF('دليل المؤشرات'!$D$11="↓",MIN('دليل المؤشرات'!$F$11/C11,1),IF('دليل المؤشرات'!$D$11="★",C11/10,MIN(C11/'دليل المؤشرات'!$F$11,1)))*'دليل المؤشرات'!$E$11,1),0))) -> 25 | J11: =IF($B11="","",IF(D11="","",IFERROR(ROUND(IF('دليل المؤشرات'!$D$12="↓",MIN('دليل المؤشرات'!$F$12/D11,1),IF('دليل المؤشرات'!$D$12="★",D11/10,MIN(D11/'دليل المؤشرات'!$F$12,1)))*'دليل المؤشرات'!$E$12,1),0))) -> 18.9 | K11: =IF($B11="","",IF(E11="","",IFERROR(ROUND(IF('دليل المؤشرات'!$D$13="↓",MIN('دليل المؤشرات'!$F$13/E11,1),IF('دليل المؤشرات'!$D$13="★",E11/10,MIN(E11/'دليل المؤشرات'!$F$13,1)))*'دليل المؤشرات'!$E$13,1),0))) -> 13.9 | L11: =IF($B11="","",IF(F11="","",IFERROR(ROUND(IF('دليل المؤشرات'!$D$14="↓",MIN('دليل المؤشرات'!$F$14/F11,1),IF('دليل المؤشرات'!$D$14="★",F11/10,MIN(F11/'دليل المؤشرات'!$F$14,1)))*'دليل المؤشرات'!$E$14,1),0))) -> 15 | M11: =IF($B11="","",IF(G11="","",IFERROR(ROUND(IF('دليل المؤشرات'!$D$15="↓",MIN('دليل المؤشرات'!$F$15/G11,1),IF('دليل المؤشرات'!$D$15="★",G11/10,MIN(G11/'دليل المؤشرات'!$F$15,1)))*'دليل المؤشرات'!$E$15,1),0))) -> 15 | N11: =IF($B11="","",IF(H11="","",IFERROR(ROUND(IF('دليل المؤشرات'!$D$16="↓",MIN('دليل المؤشرات'!$F$16/H11,1),IF('دليل المؤشرات'!$D$16="★",H11/10,MIN(H11/'دليل المؤشرات'!$F$16,1)))*'دليل المؤشرات'!$E$16,1),0))) -> 10 | O11: =IF(B11="","",ROUND(SUM(I11:N11),1)) -> 97.8 | P11: =IF(O11="","",IF(O11>=90,"أداء متميز",IF(O11>=75,"يفوق التوقعات",IF(O11>=60,"يلبّي التوقعات",IF(O11>=45,"يحتاج تطوير","غير مُرضٍ"))))) -> أداء متميز
A12: 9 | B12: بندر الرشيدي | C12: 43 | D12: 73.5 | E12: 3.7 | F12: 32 | G12: 9760 | H12: 4 | I12: =IF($B12="","",IF(C12="","",IFERROR(ROUND(IF('دليل المؤشرات'!$D$11="↓",MIN('دليل المؤشرات'!$F$11/C12,1),IF('دليل المؤشرات'!$D$11="★",C12/10,MIN(C12/'دليل المؤشرات'!$F$11,1)))*'دليل المؤشرات'!$E$11,1),0))) -> 11.9 | J12: =IF($B12="","",IF(D12="","",IFERROR(ROUND(IF('دليل المؤشرات'!$D$12="↓",MIN('دليل المؤشرات'!$F$12/D12,1),IF('دليل المؤشرات'!$D$12="★",D12/10,MIN(D12/'دليل المؤشرات'!$F$12,1)))*'دليل المؤشرات'!$E$12,1),0))) -> 8.2 | K12: =IF($B12="","",IF(E12="","",IFERROR(ROUND(IF('دليل المؤشرات'!$D$13="↓",MIN('دليل المؤشرات'!$F$13/E12,1),IF('دليل المؤشرات'!$D$13="★",E12/10,MIN(E12/'دليل المؤشرات'!$F$13,1)))*'دليل المؤشرات'!$E$13,1),0))) -> 6.9 | L12: =IF($B12="","",IF(F12="","",IFERROR(ROUND(IF('دليل المؤشرات'!$D$14="↓",MIN('دليل المؤشرات'!$F$14/F12,1),IF('دليل المؤشرات'!$D$14="★",F12/10,MIN(F12/'دليل المؤشرات'!$F$14,1)))*'دليل المؤشرات'!$E$14,1),0))) -> 6 | M12: =IF($B12="","",IF(G12="","",IFERROR(ROUND(IF('دليل المؤشرات'!$D$15="↓",MIN('دليل المؤشرات'!$F$15/G12,1),IF('دليل المؤشرات'!$D$15="★",G12/10,MIN(G12/'دليل المؤشرات'!$F$15,1)))*'دليل المؤشرات'!$E$15,1),0))) -> 6.1 | N12: =IF($B12="","",IF(H12="","",IFERROR(ROUND(IF('دليل المؤشرات'!$D$16="↓",MIN('دليل المؤشرات'!$F$16/H12,1),IF('دليل المؤشرات'!$D$16="★",H12/10,MIN(H12/'دليل المؤشرات'!$F$16,1)))*'دليل المؤشرات'!$E$16,1),0))) -> 4 | O12: =IF(B12="","",ROUND(SUM(I12:N12),1)) -> 43.1 | P12: =IF(O12="","",IF(O12>=90,"أداء متميز",IF(O12>=75,"يفوق التوقعات",IF(O12>=60,"يلبّي التوقعات",IF(O12>=45,"يحتاج تطوير","غير مُرضٍ"))))) -> غير مُرضٍ
A13: 10 | B13: لطيفة الرشيدي | C13: 80 | D13: 39.5 | E13: 7 | F13: 72 | G13: 4657 | H13: 9 | I13: =IF($B13="","",IF(C13="","",IFERROR(ROUND(IF('دليل المؤشرات'!$D$11="↓",MIN('دليل المؤشرات'!$F$11/C13,1),IF('دليل المؤشرات'!$D$11="★",C13/10,MIN(C13/'دليل المؤشرات'!$F$11,1)))*'دليل المؤشرات'!$E$11,1),0))) -> 22.2 | J13: =IF($B13="","",IF(D13="","",IFERROR(ROUND(IF('دليل المؤشرات'!$D$12="↓",MIN('دليل المؤشرات'!$F$12/D13,1),IF('دليل المؤشرات'!$D$12="★",D13/10,MIN(D13/'دليل المؤشرات'!$F$12,1)))*'دليل المؤشرات'!$E$12,1),0))) -> 15.2 | K13: =IF($B13="","",IF(E13="","",IFERROR(ROUND(IF('دليل المؤشرات'!$D$13="↓",MIN('دليل المؤشرات'!$F$13/E13,1),IF('دليل المؤشرات'!$D$13="★",E13/10,MIN(E13/'دليل المؤشرات'!$F$13,1)))*'دليل المؤشرات'!$E$13,1),0))) -> 13.1 | L13: =IF($B13="","",IF(F13="","",IFERROR(ROUND(IF('دليل المؤشرات'!$D$14="↓",MIN('دليل المؤشرات'!$F$14/F13,1),IF('دليل المؤشرات'!$D$14="★",F13/10,MIN(F13/'دليل المؤشرات'!$F$14,1)))*'دليل المؤشرات'!$E$14,1),0))) -> 13.5 | M13: =IF($B13="","",IF(G13="","",IFERROR(ROUND(IF('دليل المؤشرات'!$D$15="↓",MIN('دليل المؤشرات'!$F$15/G13,1),IF('دليل المؤشرات'!$D$15="★",G13/10,MIN(G13/'دليل المؤشرات'!$F$15,1)))*'دليل المؤشرات'!$E$15,1),0))) -> 12.9 | N13: =IF($B13="","",IF(H13="","",IFERROR(ROUND(IF('دليل المؤشرات'!$D$16="↓",MIN('دليل المؤشرات'!$F$16/H13,1),IF('دليل المؤشرات'!$D$16="★",H13/10,MIN(H13/'دليل المؤشرات'!$F$16,1)))*'دليل المؤشرات'!$E$16,1),0))) -> 9 | O13: =IF(B13="","",ROUND(SUM(I13:N13),1)) -> 85.9 | P13: =IF(O13="","",IF(O13>=90,"أداء متميز",IF(O13>=75,"يفوق التوقعات",IF(O13>=60,"يلبّي التوقعات",IF(O13>=45,"يحتاج تطوير","غير مُرضٍ"))))) -> يفوق التوقعات
